Workbook

Sheet الهه فاطمی
A1: شرکت توسعه کارآفرینی سوره کارکرد اردیبهشت 1405-الهه فاطمی
B2: روز | C2: تاریخ | D2: تعداد تردد | E2: اولین ورود | F2: آخرین خروج | G2: کارکرد | H2: کارکرد موظفی | I2: کارکرد موظف پس از کسر مرخصی | J2: اضافه کار | K2: کسرکار | L2: جمعه کاری | M2: تعطیل کاری | N2: شب کاری | O2: مرخصی | P2: نوع مرخصی | Q2: مرخصی استحقاقی | R2: مرخصی ساعتی | S2: مرخصی استعلاجی
B3: چهارشنبه | C3: 1405/01/26 | D3: 2 | E3: 08:49 | F3: 20:50 | G3: 0.50069444 | H3: 0.33333333 | I3: =MAX(H3-IF(R3="",0,R3),0) -> 0.33333333 | J3: =IF(G3>I3,G3-I3,0) -> 0.16736111 | K3: =IF(I3>G3,I3-G3,0) -> 0 | L3: 0 | M3: 0 | N3: 0 | O3: 00:00 | P3: ---
B4: پنجشنبه | C4: 1405/01/27 | E4: ---- | F4: ---- | G4: 0 | H4: 0 | I4: =MAX(H4-IF(R4="",0,R4),0) -> 0 | J4: 0 | K4: 0 | L4: 0 | M4: 0 | N4: 0 | O4: 00:00 | P4: ---
B5: جمعه | C5: 1405/01/28 | E5: ---- | F5: ---- | G5: 0 | H5: 0 | I5: 0 | J5: 0 | K5: 0 | L5: 0 | M5: 0 | N5: 0 | O5: 00:00 | P5: ---
B6: شنبه | C6: 1405/01/29 | D6: 2 | E6: 09:23 | F6: 21:00 | G6: 0.48402778 | H6: 0.375 | I6: =MAX(H6-IF(R6="",0,R6),0) -> 0.375 | J6: =IF(G6>I6,G6-I6,0) -> 0.10902778 | K6: =IF(I6>G6,I6-G6,0) -> 0 | L6: 0 | M6: 0 | N6: 0 | O6: 00:00 | P6: ---
B7: یکشنبه | C7: 1405/01/30 | D7: 2 | E7: 08:36 | F7: 19:00 | G7: 0.43333333 | H7: 0.375 | I7: =MAX(H7-IF(R7="",0,R7),0) -> 0.375 | J7: =IF(G7>I7,G7-I7,0) -> 0.058333333 | K7: =IF(I7>G7,I7-G7,0) -> 0 | L7: 0 | M7: 0 | N7: 0 | O7: 00:00 | P7: ---
B8: دوشنبه | C8: 1405/01/31 | D8: 4 | E8: 0.41111111 | F8: 00:34 | G8: 0.39513889 | H8: 0.375 | I8: =MAX(H8-IF(R8="",0,R8),0) -> 0.375 | J8: =IF(G8>I8,G8-I8,0) -> 0.020138889 | K8: =IF(I8>G8,I8-G8,0) -> 0 | L8: 0 | M8: 0 | N8: 0.10694444 | O8: 00:00 | P8: ---
B9: سه‌شنبه | C9: 1405/02/01 | D9: 2 | E9: 09:20 | F9: 19:09 | G9: 0.40902778 | H9: 0.375 | I9: =MAX(H9-IF(R9="",0,R9),0) -> 0.375 | J9: =IF(G9>I9,G9-I9,0) -> 0.034027778 | K9: =IF(I9>G9,I9-G9,0) -> 0 | L9: 0 | M9: 0 | N9: 0 | O9: 00:00 | P9: ---
B10: چهارشنبه | C10: 1405/02/02 | D10: 2 | E10: 09:01 | F10: 18:29 | G10: 0.39444444 | H10: 0.33333333 | I10: =MAX(H10-IF(R10="",0,R10),0) -> 0.33333333 | J10: =IF(G10>I10,G10-I10,0) -> 0.061111111 | K10: =IF(I10>G10,I10-G10,0) -> 0 | L10: 0 | M10: 0 | N10: 0 | O10: 00:00 | P10: ---
B11: پنجشنبه | C11: 1405/02/03 | E11: ---- | F11: ---- | G11: 0 | H11: 0 | I11: =MAX(H11-IF(R11="",0,R11),0) -> 0 | J11: 0 | K11: 0 | L11: 0 | M11: 0 | N11: 0 | O11: 00:00 | P11: ---
B12: جمعه | C12: 1405/02/04 | E12: ---- | F12: ---- | G12: 0 | H12: 0 | I12: 0 | J12: 0 | K12: 0 | L12: 0 | M12: 0 | N12: 0 | O12: 00:00 | P12: ---
B13: شنبه | C13: 1405/02/05 | D13: 4 | E13: 09:40 | F13: 20:40 | G13: 0.39583333 | H13: 0.375 | I13: =MAX(H13-IF(R13="",0,R13),0) -> 0.3125 | J13: =IF(G13>I13,G13-I13,0) -> 0.083333333 | K13: =IF(I13>G13,I13-G13,0) -> 0 | L13: 0 | M13: 0 | N13: 0 | O13: 00:00 | P13: --- | R13: 0.0625
B14: یکشنبه | C14: 1405/02/06 | D14: 2 | E14: 11:45 | F14: 18:46 | G14: 0.29236111 | H14: 0.375 | I14: =MAX(H14-IF(R14="",0,R14),0) -> 0.25 | J14: =IF(G14>I14,G14-I14,0) -> 0.042361111 | K14: =IF(I14>G14,I14-G14,0) -> 0 | L14: 0 | M14: 0 | N14: 0 | O14: 00:00 | P14: --- | R14: 0.125
B15: دوشنبه | C15: 1405/02/07 | D15: 4 | E15: 09:03 | F15: 19:23 | G15: 0.38888889 | H15: 0.375 | I15: =MAX(H15-IF(R15="",0,R15),0) -> 0.33333333 | J15: =IF(G15>I15,G15-I15,0) -> 0.055555556 | K15: =IF(I15>G15,I15-G15,0) -> 0 | L15: 0 | M15: 0 | N15: 0 | O15: 00:00 | P15: --- | R15: 0.041666667
B16: سه‌شنبه | C16: 1405/02/08 | D16: 2 | E16: 08:57 | F16: 18:41 | G16: 0.40555556 | H16: 0.375 | I16: =MAX(H16-IF(R16="",0,R16),0) -> 0.375 | J16: =IF(G16>I16,G16-I16,0) -> 0.030555556 | K16: =IF(I16>G16,I16-G16,0) -> 0 | L16: 0 | M16: 0 | N16: 0 | O16: 00:00 | P16: ---
B17: چهارشنبه | C17: 1405/02/09 | D17: 4 | E17: 09:41 | F17: 19:30 | G17: 0.36666667 | H17: 0.33333333 | I17: =MAX(H17-IF(R17="",0,R17),0) -> 0.33333333 | J17: =IF(G17>I17,G17-I17,0) -> 0.033333333 | K17: =IF(I17>G17,I17-G17,0) -> 0 | L17: 0 | M17: 0 | N17: 0 | O17: 00:00 | P17: ---
B18: پنجشنبه | C18: 1405/02/10 | E18: ---- | F18: ---- | G18: 0 | H18: 0 | I18: =MAX(H18-IF(R18="",0,R18),0) -> 0 | J18: 0 | K18: 0 | L18: 0 | M18: 0 | N18: 0 | O18: 00:00 | P18: ---
B19: جمعه | C19: 1405/02/11 | E19: ---- | F19: ---- | G19: 0 | H19: 0 | I19: 0 | J19: 0 | K19: 0 | L19: 0 | M19: 0 | N19: 0 | O19: 00:00 | P19: ---
B20: شنبه | C20: 1405/02/12 | D20: 4 | E20: 08:26 | F20: 18:44 | G20: 0.3875 | H20: 0.375 | I20: =MAX(H20-IF(R20="",0,R20),0) -> 0.33333333 | J20: =IF(G20>I20,G20-I20,0) -> 0.054166667 | K20: =IF(I20>G20,I20-G20,0) -> 0 | L20: 0 | M20: 0 | N20: 0 | O20: 00:00 | P20: --- | R20: 0.041666667
B21: یکشنبه | C21: 1405/02/13 | D21: 2 | E21: 09:40 | F21: 19:31 | G21: 0.41041667 | H21: 0.375 | I21: =MAX(H21-IF(R21="",0,R21),0) -> 0.375 | J21: =IF(G21>I21,G21-I21,0) -> 0.035416667 | K21: =IF(I21>G21,I21-G21,0) -> 0 | L21: 0 | M21: 0 | N21: 0 | O21: 00:00 | P21: ---
B22: دوشنبه | C22: 1405/02/14 | D22: 2 | E22: 09:21 | F22: 19:20 | G22: 0.41597222 | H22: 0.375 | I22: =MAX(H22-IF(R22="",0,R22),0) -> 0.375 | J22: =IF(G22>I22,G22-I22,0) -> 0.040972222 | K22: =IF(I22>G22,I22-G22,0) -> 0 | L22: 0 | M22: 0 | N22: 0 | O22: 00:00 | P22: ---
B23: سه‌شنبه | C23: 1405/02/15 | D23: 2 | E23: 09:53 | F23: 20:38 | G23: 0.44791667 | H23: 0.375 | I23: =MAX(H23-IF(R23="",0,R23),0) -> 0.375 | J23: =IF(G23>I23,G23-I23,0) -> 0.072916667 | K23: =IF(I23>G23,I23-G23,0) -> 0 | L23: 0 | M23: 0 | N23: 0 | O23: 00:00 | P23: ---
B24: چهارشنبه | C24: 1405/02/16 | D24: 2 | E24: 08:38 | F24: 19:07 | G24: 0.43680556 | H24: 0.33333333 | I24: =MAX(H24-IF(R24="",0,R24),0) -> 0.33333333 | J24: =IF(G24>I24,G24-I24,0) -> 0.10347222 | K24: =IF(I24>G24,I24-G24,0) -> 0 | L24: 0 | M24: 0 | N24: 0 | O24: 00:00 | P24: ---
B25: پنجشنبه | C25: 1405/02/17 | E25: ---- | F25: ---- | G25: 0 | H25: 0 | I25: =MAX(H25-IF(R25="",0,R25),0) -> 0 | J25: 0 | K25: 0 | L25: 0 | M25: 0 | N25: 0 | O25: 00:00 | P25: ---
B26: جمعه | C26: 1405/02/18 | E26: ---- | F26: ---- | G26: 0 | H26: 0 | I26: 0 | J26: 0 | K26: 0 | L26: 0 | M26: 0 | N26: 0 | O26: 00:00 | P26: ---
B27: شنبه | C27: 1405/02/19 | D27: 2 | E27: 09:04 | F27: 19:34 | G27: 0.4375 | H27: 0.375 | I27: =MAX(H27-IF(R27="",0,R27),0) -> 0.375 | J27: =IF(G27>I27,G27-I27,0) -> 0.0625 | K27: =IF(I27>G27,I27-G27,0) -> 0 | L27: 0 | M27: 0 | N27: 0 | O27: 00:00 | P27: ---
B28: یکشنبه | C28: 1405/02/20 | D28: 2 | E28: 09:54 | F28: 18:38 | G28: 0.36388889 | H28: 0.375 | I28: =MAX(H28-IF(R28="",0,R28),0) -> 0.375 | J28: =IF(G28>I28,G28-I28,0) -> 0 | K28: =IF(I28>G28,I28-G28,0) -> 0.011111111 | L28: 0 | M28: 0 | N28: 0 | O28: 00:00 | P28: ---
B29: دوشنبه | C29: 1405/02/21 | D29: 2 | E29: 08:11 | F29: 19:33 | G29: 0.47361111 | H29: 0.375 | I29: =MAX(H29-IF(R29="",0,R29),0) -> 0.375 | J29: =IF(G29>I29,G29-I29,0) -> 0.098611111 | K29: =IF(I29>G29,I29-G29,0) -> 0 | L29: 0 | M29: 0 | N29: 0 | O29: 00:00 | P29: ---
B30: سه‌شنبه | C30: 1405/02/22 | D30: 2 | E30: 10:02 | F30: 19:17 | G30: 0.38541667 | H30: 0.375 | I30: =MAX(H30-IF(R30="",0,R30),0) -> 0.375 | J30: =IF(G30>I30,G30-I30,0) -> 0.010416667 | K30: =IF(I30>G30,I30-G30,0) -> 0 | L30: 0 | M30: 0 | N30: 0 | O30: 00:00 | P30: ---
B31: چهارشنبه | C31: 1405/02/23 | D31: 2 | E31: 09:57 | F31: 20:43 | G31: 0.44861111 | H31: 0.33333333 | I31: =MAX(H31-IF(R31="",0,R31),0) -> 0.33333333 | J31: =IF(G31>I31,G31-I31,0) -> 0.11527778 | K31: =IF(I31>G31,I31-G31,0) -> 0 | L31: 0 | M31: 0 | N31: 0 | O31: 00:00 | P31: ---
B32: پنجشنبه | C32: 1405/02/24 | D32: 2 | E32: 17:31 | F32: 18:47 | G32: 0.052777778 | H32: 0 | I32: =MAX(H32-IF(R32="",0,R32),0) -> 0 | J32: 0 | K32: 0 | L32: 0 | M32: 0.052777778 | N32: 0 | O32: 00:00 | P32: ---
B33: جمعه | C33: 1405/02/25 | E33: ---- | F33: ---- | G33: 0 | H33: 0 | I33: 0 | J33: 0 | K33: 0 | L33: 0 | M33: 0 | N33: 0 | O33: 00:00 | P33: ---
B34: جمع | D34: =SUM(D3:D33) -> 54 | G34: =SUM(G3:G33) -> 8.7263889 | H34: =SUM(H3:H33) -> 7.6666667 | I34: =SUM(I3:I33) -> 7.3958333 | J34: =SUM(J3:J33) -> 1.2888889 | K34: =SUM(K3:K33) -> 0.011111111 | L34: =SUM(L3:L33) -> 0 | M34: =SUM(M3:M33) -> 0.052777778 | N34: =SUM(N3:N33) -> 0.10694444 | Q34: =SUM(Q3:Q33) -> 0 | R34: =SUM(R3:R33) -> 0.27083333 | S34: =SUM(S3:S33) -> 0
H36: 1.25 | I36: اضافه کار قابل پرداخت
H37: =IF(J34>=K34, J34-K34, 0) -> 1.2777778 | I37: اضافه کار واقعی
H38: =IF(K34<=J34, M34, IF(K34<=J34+M34, J34+M34-K34, 0)) -> 0.052777778 | I38: تعطیل کار واقعی
H39: =L34 -> 0 | I39: جمعه کاری
H40: =N34 -> 0.10694444 | I40: شبکاری
H41: =IF(K34>J34+M34, K34-J34-M34, 0) -> 0 | I41: کسرکار

Sheet مهدی چشمه کبودی
A1: شرکت توسعه کارآفرینی سوره کارکرد اردیبهشت 1405-مهدی چشمه کبودی
B2: روز | C2: تاریخ | D2: تعداد تردد | E2: اولین ورود | F2: آخرین خروج | G2: کارکرد | H2: کارکرد موظفی | I2: کارکرد موظف پس از کسر مرخصی | J2: اضافه کار | K2: کسرکار | L2: جمعه کاری | M2: تعطیل کاری | N2: شب کاری | O2: مرخصی | P2: نوع مرخصی | Q2: مرخصی استحقاقی | R2: مرخصی ساعتی | S2: مرخصی استعلاجی
B3: چهارشنبه | C3: 1405/01/26 | D3: 2 | E3: 08:50 | F3: 22:00 | G3: 0.54861111 | H3: 0.33333333 | I3: =MAX(H3-IF(R3="",0,R3),0) -> 0.33333333 | J3: =IF(G3>I3,G3-I3,0) -> 0.21527778 | K3: =IF(I3>G3,I3-G3,0) -> 0 | L3: 0 | M3: 0 | N3: 0 | O3: 00:00 | P3: ---
B4: پنجشنبه | C4: 1405/01/27 | D4: 2 | E4: 07:45 | F4: 18:00 | G4: 0.42708333 | H4: 0 | I4: =MAX(H4-IF(R4="",0,R4),0) -> 0 | J4: 0 | K4: 0 | L4: 0 | M4: 0.42708333 | N4: 0 | O4: 00:00 | P4: ---
B5: جمعه | C5: 1405/01/28 | D5: 2 | E5: 14:00 | F5: 15:30 | G5: 0.0625 | H5: 0 | I5: 0 | J5: 0 | K5: 0 | L5: 0.0625 | M5: 0 | N5: 0 | O5: 00:00 | P5: ---
B6: شنبه | C6: 1405/01/29 | D6: 2 | E6: 07:45 | F6: 21:15 | G6: 0.5625 | H6: 0.375 | I6: =MAX(H6-IF(R6="",0,R6),0) -> 0.375 | J6: =IF(G6>I6,G6-I6,0) -> 0.1875 | K6: =IF(I6>G6,I6-G6,0) -> 0 | L6: 0 | M6: 0 | N6: 0 | O6: 00:00 | P6: ---
B7: یکشنبه | C7: 1405/01/30 | D7: 2 | E7: 07:50 | F7: 22:20 | G7: 0.60416667 | H7: 0.375 | I7: =MAX(H7-IF(R7="",0,R7),0) -> 0.375 | J7: =IF(G7>I7,G7-I7,0) -> 0.22916667 | K7: =IF(I7>G7,I7-G7,0) -> 0 | L7: 0 | M7: 0 | N7: 0.013888889 | O7: 00:00 | P7: ---
B8: دوشنبه | C8: 1405/01/31 | D8: 2 | E8: 08:00 | F8: 23:20 | G8: 0.63888889 | H8: 0.375 | I8: =MAX(H8-IF(R8="",0,R8),0) -> 0.375 | J8: =IF(G8>I8,G8-I8,0) -> 0.26388889 | K8: =IF(I8>G8,I8-G8,0) -> 0 | L8: 0 | M8: 0 | N8: 0.055555556 | O8: 00:00 | P8: ---
B9: سه‌شنبه | C9: 1405/02/01 | E9: ---- | F9: ---- | G9: 0 | H9: 0.375 | I9: 0 | J9: =IF(G9>I9,G9-I9,0) -> 0 | K9: =IF(I9>G9,I9-G9,0) -> 0 | L9: 0 | M9: 0 | N9: 0 | O9: 00:00 | P9: --- | Q9: 1
B10: چهارشنبه | C10: 1405/02/02 | E10: ---- | F10: ---- | G10: 0 | H10: 0.33333333 | I10: 0 | J10: =IF(G10>I10,G10-I10,0) -> 0 | K10: =IF(I10>G10,I10-G10,0) -> 0 | L10: 0 | M10: 0 | N10: 0 | O10: 00:00 | P10: --- | Q10: 1
B11: پنجشنبه | C11: 1405/02/03 | E11: ---- | F11: ---- | G11: 0 | H11: 0 | I11: =MAX(H11-IF(R11="",0,R11),0) -> 0 | J11: 0 | K11: 0 | L11: 0 | M11: 0 | N11: 0 | O11: 00:00 | P11: ---
B12: جمعه | C12: 1405/02/04 | E12: ---- | F12: ---- | G12: 0 | H12: 0 | I12: 0 | J12: 0 | K12: 0 | L12: 0 | M12: 0 | N12: 0 | O12: 00:00 | P12: ---
B13: شنبه | C13: 1405/02/05 | E13: ---- | F13: ---- | G13: 0 | H13: 0.375 | I13: 0 | J13: =IF(G13>I13,G13-I13,0) -> 0 | K13: =IF(I13>G13,I13-G13,0) -> 0 | L13: 0 | M13: 0 | N13: 0 | O13: 00:00 | P13: --- | Q13: 1
B14: یکشنبه | C14: 1405/02/06 | E14: ---- | F14: ---- | G14: 0 | H14: 0.375 | I14: 0 | J14: =IF(G14>I14,G14-I14,0) -> 0 | K14: =IF(I14>G14,I14-G14,0) -> 0 | L14: 0 | M14: 0 | N14: 0 | O14: 00:00 | P14: --- | Q14: 1
B15: دوشنبه | C15: 1405/02/07 | E15: ---- | F15: ---- | G15: 0 | H15: 0.375 | I15: 0 | J15: =IF(G15>I15,G15-I15,0) -> 0 | K15: =IF(I15>G15,I15-G15,0) -> 0 | L15: 0 | M15: 0 | N15: 0 | O15: 00:00 | P15: --- | Q15: 1
B16: سه‌شنبه | C16: 1405/02/08 | D16: 2 | E16: 08:15 | F16: 23:10 | G16: 0.62152778 | H16: 0.375 | I16: 0 | J16: =IF(G16>I16,G16-I16,0) -> 0.62152778 | K16: =IF(I16>G16,I16-G16,0) -> 0 | L16: 0 | M16: 0 | N16: 0.048611111 | O16: 00:00 | P16: ---
B17: چهارشنبه | C17: 1405/02/09 | D17: 2 | E17: 08:30 | F17: 23:20 | G17: 0.61805556 | H17: 0.33333333 | I17: =MAX(H17-IF(R17="",0,R17),0) -> 0.33333333 | J17: =IF(G17>I17,G17-I17,0) -> 0.28472222 | K17: =IF(I17>G17,I17-G17,0) -> 0 | L17: 0 | M17: 0 | N17: 0.055555556 | O17: 00:00 | P17: ---
B18: پنجشنبه | C18: 1405/02/10 | D18: 2 | E18: 08:00 | F18: 19:40 | G18: 0.48611111 | H18: 0 | I18: =MAX(H18-IF(R18="",0,R18),0) -> 0 | J18: 0 | K18: 0 | L18: 0 | M18: 0.48611111 | N18: 0 | O18: 00:00 | P18: ---
B19: جمعه | C19: 1405/02/11 | E19: ---- | F19: ---- | G19: 0 | H19: 0 | I19: 0 | J19: 0 | K19: 0 | L19: 0 | M19: 0 | N19: 0 | O19: 00:00 | P19: ---
B20: شنبه | C20: 1405/02/12 | D20: 2 | E20: 08:00 | F20: 20:55 | G20: 0.53819444 | H20: 0.375 | I20: =MAX(H20-IF(R20="",0,R20),0) -> 0.375 | J20: =IF(G20>I20,G20-I20,0) -> 0.16319444 | K20: =IF(I20>G20,I20-G20,0) -> 0 | L20: 0 | M20: 0 | N20: 0 | O20: 00:00 | P20: ---
B21: یکشنبه | C21: 1405/02/13 | D21: 2 | E21: 07:45 | F21: 21:30 | G21: 0.57291667 | H21: 0.375 | I21: =MAX(H21-IF(R21="",0,R21),0) -> 0.375 | J21: =IF(G21>I21,G21-I21,0) -> 0.19791667 | K21: =IF(I21>G21,I21-G21,0) -> 0 | L21: 0 | M21: 0 | N21: 0 | O21: 00:00 | P21: ---
B22: دوشنبه | C22: 1405/02/14 | D22: 2 | E22: 06:40 | F22: 21:45 | G22: 0.62847222 | H22: 0.375 | I22: =MAX(H22-IF(R22="",0,R22),0) -> 0.375 | J22: =IF(G22>I22,G22-I22,0) -> 0.25347222 | K22: =IF(I22>G22,I22-G22,0) -> 0 | L22: 0 | M22: 0 | N22: 0 | O22: 00:00 | P22: ---
B23: سه‌شنبه | C23: 1405/02/15 | D23: 2 | E23: 08:00 | F23: 21:30 | G23: 0.5625 | H23: 0.375 | I23: =MAX(H23-IF(R23="",0,R23),0) -> 0.375 | J23: =IF(G23>I23,G23-I23,0) -> 0.1875 | K23: =IF(I23>G23,I23-G23,0) -> 0 | L23: 0 | M23: 0 | N23: 0 | O23: 00:00 | P23: ---
B24: چهارشنبه | C24: 1405/02/16 | D24: 2 | E24: 06:35 | F24: 21:20 | G24: 0.61458333 | H24: 0.33333333 | I24: =MAX(H24-IF(R24="",0,R24),0) -> 0.33333333 | J24: =IF(G24>I24,G24-I24,0) -> 0.28125 | K24: =IF(I24>G24,I24-G24,0) -> 0 | L24: 0 | M24: 0 | N24: 0 | O24: 00:00 | P24: ---
B25: پنجشنبه | C25: 1405/02/17 | D25: 2 | E25: 09:00 | F25: 14:30 | G25: 0.22916667 | H25: 0 | I25: =MAX(H25-IF(R25="",0,R25),0) -> 0 | J25: 0 | K25: 0 | L25: 0 | M25: 0.22916667 | N25: 0 | O25: 00:00 | P25: ---
B26: جمعه | C26: 1405/02/18 | D26: 2 | E26: 09:30 | F26: 12:30 | G26: 0.125 | H26: 0 | I26: 0 | J26: 0 | K26: 0 | L26: 0.125 | M26: 0 | N26: 0 | O26: 00:00 | P26: ---
B27: شنبه | C27: 1405/02/19 | D27: 2 | E27: 08:45 | F27: 22:30 | G27: 0.57291667 | H27: 0.375 | I27: =MAX(H27-IF(R27="",0,R27),0) -> 0.375 | J27: =IF(G27>I27,G27-I27,0) -> 0.19791667 | K27: =IF(I27>G27,I27-G27,0) -> 0 | L27: 0 | M27: 0 | N27: 0.020833333 | O27: 00:00 | P27: ---
B28: یکشنبه | C28: 1405/02/20 | D28: 2 | E28: 09:00 | F28: 22:45 | G28: 0.57291667 | H28: 0.375 | I28: =MAX(H28-IF(R28="",0,R28),0) -> 0.375 | J28: =IF(G28>I28,G28-I28,0) -> 0.19791667 | K28: =IF(I28>G28,I28-G28,0) -> 0 | L28: 0 | M28: 0 | N28: 0.03125 | O28: 00:00 | P28: ---
B29: دوشنبه | C29: 1405/02/21 | D29: 2 | E29: 09:20 | F29: 21:45 | G29: 0.51736111 | H29: 0.375 | I29: =MAX(H29-IF(R29="",0,R29),0) -> 0.375 | J29: =IF(G29>I29,G29-I29,0) -> 0.14236111 | K29: =IF(I29>G29,I29-G29,0) -> 0 | L29: 0 | M29: 0 | N29: 0 | O29: 00:00 | P29: ---
B30: سه‌شنبه | C30: 1405/02/22 | D30: 2 | E30: 09:25 | F30: 21:50 | G30: 0.51736111 | H30: 0.375 | I30: =MAX(H30-IF(R30="",0,R30),0) -> 0.375 | J30: =IF(G30>I30,G30-I30,0) -> 0.14236111 | K30: =IF(I30>G30,I30-G30,0) -> 0 | L30: 0 | M30: 0 | N30: 0 | O30: 00:00 | P30: ---
B31: چهارشنبه | C31: 1405/02/23 | D31: 2 | E31: 09:15 | F31: 22:05 | G31: 0.53472222 | H31: 0.33333333 | I31: =MAX(H31-IF(R31="",0,R31),0) -> 0.33333333 | J31: =IF(G31>I31,G31-I31,0) -> 0.20138889 | K31: =IF(I31>G31,I31-G31,0) -> 0 | L31: 0 | M31: 0 | N31: 0.0034722222 | O31: 00:00 | P31: ---
B32: پنجشنبه | C32: 1405/02/24 | D32: 2 | E32: 08:00 | F32: 19:00 | G32: 0.45833333 | H32: 0 | I32: =MAX(H32-IF(R32="",0,R32),0) -> 0 | J32: 0 | K32: 0 | L32: 0 | M32: 0.45833333 | N32: 0 | O32: 00:00 | P32: ---
B33: جمعه | C33: 1405/02/25 | E33: ---- | F33: ---- | G33: 0 | H33: 0 | I33: 0 | J33: 0 | K33: 0 | L33: 0 | M33: 0 | N33: 0 | O33: 00:00 | P33: ---
B34: جمع | D34: =SUM(D3:D33) -> 44 | G34: =SUM(G3:G33) -> 11.013889 | H34: =SUM(H3:H33) -> 7.6666667 | I34: =SUM(I3:I33) -> 5.4583333 | J34: =SUM(J3:J33) -> 3.7673611 | K34: =SUM(K3:K33) -> 0 | L34: =SUM(L3:L33) -> 0.1875 | M34: =SUM(M3:M33) -> 1.6006944 | N34: =SUM(N3:N33) -> 0.22916667 | Q34: =SUM(Q3:Q33) -> 5 | R34: =SUM(R3:R33) -> 0 | S34: =SUM(S3:S33) -> 0
H36: =IF(J34>=K34, J34-K34, 0) -> 3.7673611 | I36: اضافه کار واقعی
H37: =IF(K34<=J34, M34, IF(K34<=J34+M34, J34+M34-K34, 0)) -> 1.6006944 | I37: تعطیل کار
H38: =L34 -> 0.1875 | I38: جمعه کاری
H39: =N34 -> 0.22916667 | I39: شبکاری
H40: =IF(K34>J34+M34, K34-J34-M34, 0) -> 0 | I40: کسرکار واقعی

Sheet حمید محمدپور نشرودکل
A1: شرکت توسعه کارآفرینی سوره کارکرد اردیبهشت 1405-حمید محمدپور نشرودکل
B2: روز | C2: تاریخ | D2: تعداد تردد | E2: اولین ورود | F2: آخرین خروج | G2: کارکرد | H2: کارکرد موظفی | I2: کارکرد موظف پس از کسر مرخصی | J2: اضافه کار | K2: کسرکار | L2: جمعه کاری | M2: تعطیل کاری | N2: شب کاری | O2: مرخصی | P2: نوع مرخصی | Q2: مرخصی استحقاقی | R2: مرخصی ساعتی | S2: مرخصی استعلاجی
B3: چهارشنبه | C3: 1405/01/26 | E3: ---- | F3: ---- | G3: 0 | H3: 0.33333333 | I3: 0 | J3: =IF(G3>I3,G3-I3,0) -> 0 | K3: =IF(I3>G3,I3-G3,0) -> 0 | L3: 0 | M3: 0 | N3: 0 | O3: 00:00 | P3: --- | Q3: 1
B4: پنجشنبه | C4: 1405/01/27 | E4: ---- | F4: ---- | G4: 0 | H4: 0 | I4: =MAX(H4-IF(R4="",0,R4),0) -> 0 | J4: 0 | K4: 0 | L4: 0 | M4: 0 | N4: 0 | O4: 00:00 | P4: ---
B5: جمعه | C5: 1405/01/28 | E5: ---- | F5: ---- | G5: 0 | H5: 0 | I5: 0 | J5: 0 | K5: 0 | L5: 0 | M5: 0 | N5: 0 | O5: 00:00 | P5: ---
B6: شنبه | C6: 1405/01/29 | D6: 2 | E6: 07:58 | F6: 22:12 | G6: 0.59305556 | H6: 0.375 | I6: =MAX(H6-IF(R6="",0,R6),0) -> 0.375 | J6: =IF(G6>I6,G6-I6,0) -> 0.21805556 | K6: =IF(I6>G6,I6-G6,0) -> 0 | L6: 0 | M6: 0 | N6: 0.0083333333 | O6: 00:00 | P6: ---
B7: یکشنبه | C7: 1405/01/30 | D7: 2 | E7: 07:54 | F7: 22:26 | G7: 0.60555556 | H7: 0.375 | I7: =MAX(H7-IF(R7="",0,R7),0) -> 0.375 | J7: =IF(G7>I7,G7-I7,0) -> 0.23055556 | K7: =IF(I7>G7,I7-G7,0) -> 0 | L7: 0 | M7: 0 | N7: 0.018055556 | O7: 00:00 | P7: ---
B8: دوشنبه | C8: 1405/01/31 | D8: 2 | E8: 08:19 | F8: 22:35 | G8: 0.59444444 | H8: 0.375 | I8: =MAX(H8-IF(R8="",0,R8),0) -> 0.375 | J8: =IF(G8>I8,G8-I8,0) -> 0.21944444 | K8: =IF(I8>G8,I8-G8,0) -> 0 | L8: 0 | M8: 0 | N8: 0.024305556 | O8: 00:00 | P8: ---
B9: سه‌شنبه | C9: 1405/02/01 | D9: 2 | E9: 07:48 | F9: 22:52 | G9: 0.62777778 | H9: 0.375 | I9: =MAX(H9-IF(R9="",0,R9),0) -> 0.375 | J9: =IF(G9>I9,G9-I9,0) -> 0.25277778 | K9: =IF(I9>G9,I9-G9,0) -> 0 | L9: 0 | M9: 0 | N9: 0.036111111 | O9: 00:00 | P9: ---
B10: چهارشنبه | C10: 1405/02/02 | D10: 2 | E10: 07:27 | F10: 22:30 | G10: 0.62708333 | H10: 0.33333333 | I10: =MAX(H10-IF(R10="",0,R10),0) -> 0.33333333 | J10: =IF(G10>I10,G10-I10,0) -> 0.29375 | K10: =IF(I10>G10,I10-G10,0) -> 0 | L10: 0 | M10: 0 | N10: 0.020833333 | O10: 00:00 | P10: ---
B11: پنجشنبه | C11: 1405/02/03 | E11: ---- | F11: ---- | G11: 0 | H11: 0 | I11: =MAX(H11-IF(R11="",0,R11),0) -> 0 | J11: 0 | K11: 0 | L11: 0 | M11: 0 | N11: 0 | O11: 00:00 | P11: ---
B12: جمعه | C12: 1405/02/04 | E12: ---- | F12: ---- | G12: 0 | H12: 0 | I12: 0 | J12: 0 | K12: 0 | L12: 0 | M12: 0 | N12: 0 | O12: 00:00 | P12: ---
B13: شنبه | C13: 1405/02/05 | D13: 2 | E13: 07:32 | F13: 23:06 | G13: 0.64861111 | H13: 0.375 | I13: =MAX(H13-IF(R13="",0,R13),0) -> 0.375 | J13: =IF(G13>I13,G13-I13,0) -> 0.27361111 | K13: =IF(I13>G13,I13-G13,0) -> 0 | L13: 0 | M13: 0 | N13: 0.045833333 | O13: 00:00 | P13: ---
B14: یکشنبه | C14: 1405/02/06 | D14: 2 | E14: 06:01 | F14: 22:21 | G14: 0.68055556 | H14: 0.375 | I14: =MAX(H14-IF(R14="",0,R14),0) -> 0.375 | J14: =IF(G14>I14,G14-I14,0) -> 0.30555556 | K14: =IF(I14>G14,I14-G14,0) -> 0 | L14: 0 | M14: 0 | N14: 0.014583333 | O14: 00:00 | P14: ---
B15: دوشنبه | C15: 1405/02/07 | D15: 2 | E15: 06:12 | F15: 22:15 | G15: 0.66875 | H15: 0.375 | I15: =MAX(H15-IF(R15="",0,R15),0) -> 0.375 | J15: =IF(G15>I15,G15-I15,0) -> 0.29375 | K15: =IF(I15>G15,I15-G15,0) -> 0 | L15: 0 | M15: 0 | N15: 0.010416667 | O15: 00:00 | P15: ---
B16: سه‌شنبه | C16: 1405/02/08 | D16: 2 | E16: 06:31 | F16: 23:33 | G16: 0.70972222 | H16: 0.375 | I16: =MAX(H16-IF(R16="",0,R16),0) -> 0.375 | J16: =IF(G16>I16,G16-I16,0) -> 0.33472222 | K16: =IF(I16>G16,I16-G16,0) -> 0 | L16: 0 | M16: 0 | N16: 0.064583333 | O16: 00:00 | P16: ---
B17: چهارشنبه | C17: 1405/02/09 | D17: 2 | E17: 07:47 | F17: 00:20 | G17: 0.68958333 | H17: 0.33333333 | I17: =MAX(H17-IF(R17="",0,R17),0) -> 0.33333333 | J17: =IF(G17>I17,G17-I17,0) -> 0.35625 | K17: =IF(I17>G17,I17-G17,0) -> 0 | L17: 0 | M17: 0 | N17: 0.097222222 | O17: 00:00 | P17: ---
B18: پنجشنبه | C18: 1405/02/10 | D18: 2 | E18: 0.33888889 | F18: 0.82013889 | G18: 0.48125 | H18: 0 | I18: =MAX(H18-IF(R18="",0,R18),0) -> 0 | J18: 0 | K18: 0 | L18: 0 | M18: 0.48125 | N18: 0 | O18: 00:00 | P18: ---
B19: جمعه | C19: 1405/02/11 | E19: ---- | F19: ---- | G19: 0 | H19: 0 | I19: 0 | J19: 0 | K19: 0 | L19: 0 | M19: 0 | N19: 0 | O19: 00:00 | P19: ---
B20: شنبه | C20: 1405/02/12 | D20: 2 | E20: 07:41 | F20: 23:19 | G20: 0.65138889 | H20: 0.375 | I20: =MAX(H20-IF(R20="",0,R20),0) -> 0.375 | J20: =IF(G20>I20,G20-I20,0) -> 0.27638889 | K20: =IF(I20>G20,I20-G20,0) -> 0 | L20: 0 | M20: 0 | N20: 0.054861111 | O20: 00:00 | P20: ---
B21: یکشنبه | C21: 1405/02/13 | D21: 2 | E21: 07:43 | F21: 23:01 | G21: 0.6375 | H21: 0.375 | I21: =MAX(H21-IF(R21="",0,R21),0) -> 0.375 | J21: =IF(G21>I21,G21-I21,0) -> 0.2625 | K21: =IF(I21>G21,I21-G21,0) -> 0 | L21: 0 | M21: 0 | N21: 0.042361111 | O21: 00:00 | P21: ---
B22: دوشنبه | C22: 1405/02/14 | D22: 2 | E22: 06:00 | F22: 21:26 | G22: 0.64305556 | H22: 0.375 | I22: =MAX(H22-IF(R22="",0,R22),0) -> 0.375 | J22: =IF(G22>I22,G22-I22,0) -> 0.26805556 | K22: =IF(I22>G22,I22-G22,0) -> 0 | L22: 0 | M22: 0 | N22: 0 | O22: 00:00 | P22: ---
B23: سه‌شنبه | C23: 1405/02/15 | D23: 4 | E23: 07:53 | F23: 05:59 | G23: 0.63125 | H23: 0.375 | I23: =MAX(H23-IF(R23="",0,R23),0) -> 0.375 | J23: =IF(G23>I23,G23-I23,0) -> 0.25625 | K23: =IF(I23>G23,I23-G23,0) -> 0 | L23: 0 | M23: 0 | N23: 0.043055556 | O23: 00:00 | P23: ---
B24: چهارشنبه | C24: 1405/02/16 | D24: 2 | E24: 06:01 | F24: 14:25 | G24: 0.35 | H24: 0.33333333 | I24: =MAX(H24-IF(R24="",0,R24),0) -> 0.33333333 | J24: =IF(G24>I24,G24-I24,0) -> 0.016666667 | K24: =IF(I24>G24,I24-G24,0) -> 0 | L24: 0 | M24: 0 | N24: 0 | O24: 00:00 | P24: ---
B25: پنجشنبه | C25: 1405/02/17 | E25: ---- | F25: ---- | G25: 0 | H25: 0 | I25: =MAX(H25-IF(R25="",0,R25),0) -> 0 | J25: 0 | K25: 0 | L25: 0 | M25: 0 | N25: 0 | O25: 00:00 | P25: ---
B26: جمعه | C26: 1405/02/18 | E26: ---- | F26: ---- | G26: 0 | H26: 0 | I26: 0 | J26: 0 | K26: 0 | L26: 0 | M26: 0 | N26: 0 | O26: 00:00 | P26: ---
B27: شنبه | C27: 1405/02/19 | D27: 2 | E27: 07:42 | F27: 22:02 | G27: 0.59722222 | H27: 0.375 | I27: =MAX(H27-IF(R27="",0,R27),0) -> 0.375 | J27: =IF(G27>I27,G27-I27,0) -> 0.22222222 | K27: =IF(I27>G27,I27-G27,0) -> 0 | L27: 0 | M27: 0 | N27: 0.0013888889 | O27: 00:00 | P27: ---
B28: یکشنبه | C28: 1405/02/20 | D28: 2 | E28: 07:49 | F28: 22:11 | G28: 0.59861111 | H28: 0.375 | I28: =MAX(H28-IF(R28="",0,R28),0) -> 0.375 | J28: =IF(G28>I28,G28-I28,0) -> 0.22361111 | K28: =IF(I28>G28,I28-G28,0) -> 0 | L28: 0 | M28: 0 | N28: 0.0076388889 | O28: 00:00 | P28: ---
B29: دوشنبه | C29: 1405/02/21 | D29: 2 | E29: 07:36 | F29: 22:13 | G29: 0.60902778 | H29: 0.375 | I29: =MAX(H29-IF(R29="",0,R29),0) -> 0.375 | J29: =IF(G29>I29,G29-I29,0) -> 0.23402778 | K29: =IF(I29>G29,I29-G29,0) -> 0 | L29: 0 | M29: 0 | N29: 0.0090277778 | O29: 00:00 | P29: ---
B30: سه‌شنبه | C30: 1405/02/22 | D30: 2 | E30: 06:03 | F30: 22:10 | G30: 0.67152778 | H30: 0.375 | I30: =MAX(H30-IF(R30="",0,R30),0) -> 0.375 | J30: =IF(G30>I30,G30-I30,0) -> 0.29652778 | K30: =IF(I30>G30,I30-G30,0) -> 0 | L30: 0 | M30: 0 | N30: 0.0069444444 | O30: 00:00 | P30: ---
B31: چهارشنبه | C31: 1405/02/23 | D31: 2 | E31: 07:45 | F31: 22:57 | G31: 0.63333333 | H31: 0.33333333 | I31: =MAX(H31-IF(R31="",0,R31),0) -> 0.33333333 | J31: =IF(G31>I31,G31-I31,0) -> 0.3 | K31: =IF(I31>G31,I31-G31,0) -> 0 | L31: 0 | M31: 0 | N31: 0.039583333 | O31: 00:00 | P31: ---
B32: پنجشنبه | C32: 1405/02/24 | E32: ---- | F32: ---- | G32: 0 | H32: 0 | I32: =MAX(H32-IF(R32="",0,R32),0) -> 0 | J32: 0 | K32: 0 | L32: 0 | M32: 0 | N32: 0 | O32: 00:00 | P32: ---
B33: جمعه | C33: 1405/02/25 | E33: ---- | F33: ---- | G33: 0 | H33: 0 | I33: 0 | J33: 0 | K33: 0 | L33: 0 | M33: 0 | N33: 0 | O33: 00:00 | P33: ---
B34: جمع | D34: =SUM(D3:D33) -> 44 | G34: =SUM(G3:G33) -> 12.949306 | H34: =SUM(H3:H33) -> 7.6666667 | I34: =SUM(I3:I33) -> 7.3333333 | J34: =SUM(J3:J33) -> 5.1347222 | K34: =SUM(K3:K33) -> 0 | L34: =SUM(L3:L33) -> 0 | M34: =SUM(M3:M33) -> 0.48125 | N34: =SUM(N3:N33) -> 0.54513889 | Q34: =SUM(Q3:Q33) -> 1 | R34: =SUM(R3:R33) -> 0 | S34: =SUM(S3:S33) -> 0
H36: =IF(J34>=K34, J34-K34, 0) -> 5.1347222 | I36: اضافه کار واقعی
H37: =IF(K34<=J34, M34, IF(K34<=J34+M34, J34+M34-K34, 0)) -> 0.48125 | I37: تعطیل کار واقعی
H38: =L34 -> 0 | I38: جمعه کاری
H39: =N34 -> 0.54513889 | I39: شبکاری
H40: =IF(K34>J34+M34, K34-J34-M34, 0) -> 0 | I40: کسرکار

Sheet محمدسجاد زارع میرک آباد
A1: شرکت توسعه کارآفرینی سوره کارکرد اردیبهشت 1405-محمدسجاد زارع میرک آباد
B2: روز | C2: تاریخ | D2: تعداد تردد | E2: اولین ورود | F2: آخرین خروج | G2: کارکرد | H2: کارکرد موظفی | I2: کارکرد موظف پس از کسر مرخصی | J2: اضافه کار | K2: کسرکار | L2: جمعه کاری | M2: تعطیل کاری | N2: شب کاری | O2: مرخصی | P2: نوع مرخصی | Q2: مرخصی استحقاقی | R2: مرخصی ساعتی | S2: مرخصی استعلاجی
B3: چهارشنبه | C3: 1405/01/26 | D3: 2 | E3: 09:00 | F3: 19:56 | G3: 0.45555556 | H3: 0.33333333 | I3: =MAX(H3-IF(R3="",0,R3),0) -> 0.33333333 | J3: =IF(G3>I3,G3-I3,0) -> 0.12222222 | K3: =IF(I3>G3,I3-G3,0) -> 0 | L3: 0 | M3: 0 | N3: 0 | O3: 00:00 | P3: ---
B4: پنجشنبه | C4: 1405/01/27 | E4: ---- | F4: ---- | G4: 0 | H4: 0 | I4: =MAX(H4-IF(R4="",0,R4),0) -> 0 | J4: 0 | K4: 0 | L4: 0 | M4: 0 | N4: 0 | O4: 00:00 | P4: ---
B5: جمعه | C5: 1405/01/28 | E5: ---- | F5: ---- | G5: 0 | H5: 0 | I5: 0 | J5: 0 | K5: 0 | L5: 0 | M5: 0 | N5: 0 | O5: 00:00 | P5: ---
B6: شنبه | C6: 1405/01/29 | D6: 2 | E6: 09:25 | F6: 20:26 | G6: 0.45902778 | H6: 0.375 | I6: =MAX(H6-IF(R6="",0,R6),0) -> 0.375 | J6: =IF(G6>I6,G6-I6,0) -> 0.084027778 | K6: =IF(I6>G6,I6-G6,0) -> 0 | L6: 0 | M6: 0 | N6: 0 | O6: 00:00 | P6: ---
B7: یکشنبه | C7: 1405/01/30 | D7: 2 | E7: 09:26 | F7: 18:39 | G7: 0.38402778 | H7: 0.375 | I7: =MAX(H7-IF(R7="",0,R7),0) -> 0.375 | J7: =IF(G7>I7,G7-I7,0) -> 0.0090277778 | K7: =IF(I7>G7,I7-G7,0) -> 0 | L7: 0 | M7: 0 | N7: 0 | O7: 00:00 | P7: ---
B8: دوشنبه | C8: 1405/01/31 | D8: 2 | E8: 09:30 | F8: 19:48 | G8: 0.42916667 | H8: 0.375 | I8: =MAX(H8-IF(R8="",0,R8),0) -> 0.375 | J8: =IF(G8>I8,G8-I8,0) -> 0.054166667 | K8: =IF(I8>G8,I8-G8,0) -> 0 | L8: 0 | M8: 0 | N8: 0 | O8: 00:00 | P8: ---
B9: سه‌شنبه | C9: 1405/02/01 | D9: 2 | E9: 11:00 | F9: 17:00 | G9: 0.25 | H9: 0.375 | I9: =MAX(H9-IF(R9="",0,R9),0) -> 0.25 | J9: =IF(G9>I9,G9-I9,0) -> 0 | K9: =IF(I9>G9,I9-G9,0) -> 0 | L9: 0 | M9: 0 | N9: 0 | O9: 00:00 | P9: --- | R9: 0.125
B10: چهارشنبه | C10: 1405/02/02 | D10: 2 | E10: 09:00 | F10: 18:47 | G10: 0.40763889 | H10: 0.33333333 | I10: =MAX(H10-IF(R10="",0,R10),0) -> 0.33333333 | J10: =IF(G10>I10,G10-I10,0) -> 0.074305556 | K10: =IF(I10>G10,I10-G10,0) -> 0 | L10: 0 | M10: 0 | N10: 0 | O10: 00:00 | P10: ---
B11: پنجشنبه | C11: 1405/02/03 | E11: ---- | F11: ---- | G11: 0 | H11: 0 | I11: =MAX(H11-IF(R11="",0,R11),0) -> 0 | J11: 0 | K11: 0 | L11: 0 | M11: 0 | N11: 0 | O11: 00:00 | P11: ---
B12: جمعه | C12: 1405/02/04 | E12: ---- | F12: ---- | G12: 0 | H12: 0 | I12: 0 | J12: 0 | K12: 0 | L12: 0 | M12: 0 | N12: 0 | O12: 00:00 | P12: ---
B13: شنبه | C13: 1405/02/05 | D13: 2 | E13: 11:00 | F13: 17:00 | G13: 0.25 | H13: 0.375 | I13: =MAX(H13-IF(R13="",0,R13),0) -> 0.25 | J13: =IF(G13>I13,G13-I13,0) -> 0 | K13: =IF(I13>G13,I13-G13,0) -> 0 | L13: 0 | M13: 0 | N13: 0 | O13: 00:00 | P13: --- | R13: 0.125
B14: یکشنبه | C14: 1405/02/06 | D14: 2 | E14: 09:00 | F14: 20:00 | G14: 0.45833333 | H14: 0.375 | I14: =MAX(H14-IF(R14="",0,R14),0) -> 0.375 | J14: =IF(G14>I14,G14-I14,0) -> 0.083333333 | K14: =IF(I14>G14,I14-G14,0) -> 0 | L14: 0 | M14: 0 | N14: 0 | O14: 00:00 | P14: ---
B15: دوشنبه | C15: 1405/02/07 | D15: 2 | E15: 10:00 | F15: 20:28 | G15: 0.43611111 | H15: 0.375 | I15: =MAX(H15-IF(R15="",0,R15),0) -> 0.375 | J15: =IF(G15>I15,G15-I15,0) -> 0.061111111 | K15: =IF(I15>G15,I15-G15,0) -> 0 | L15: 0 | M15: 0 | N15: 0 | O15: 00:00 | P15: ---
B16: سه‌شنبه | C16: 1405/02/08 | D16: 2 | E16: 09:00 | F16: 18:00 | G16: 0.375 | H16: 0.375 | I16: =MAX(H16-IF(R16="",0,R16),0) -> 0.375 | J16: =IF(G16>I16,G16-I16,0) -> 0 | K16: =IF(I16>G16,I16-G16,0) -> 0 | L16: 0 | M16: 0 | N16: 0 | O16: 00:00 | P16: ---
B17: چهارشنبه | C17: 1405/02/09 | D17: 2 | E17: 09:57 | F17: 20:00 | G17: 0.41875 | H17: 0.33333333 | I17: =MAX(H17-IF(R17="",0,R17),0) -> 0.33333333 | J17: =IF(G17>I17,G17-I17,0) -> 0.085416667 | K17: =IF(I17>G17,I17-G17,0) -> 0 | L17: 0 | M17: 0 | N17: 0 | O17: 00:00 | P17: ---
B18: پنجشنبه | C18: 1405/02/10 | E18: ---- | F18: ---- | G18: 0 | H18: 0 | I18: =MAX(H18-IF(R18="",0,R18),0) -> 0 | J18: 0 | K18: 0 | L18: 0 | M18: 0 | N18: 0 | O18: 00:00 | P18: ---
B19: جمعه | C19: 1405/02/11 | E19: ---- | F19: ---- | G19: 0 | H19: 0 | I19: 0 | J19: 0 | K19: 0 | L19: 0 | M19: 0 | N19: 0 | O19: 00:00 | P19: ---
B20: شنبه | C20: 1405/02/12 | D20: 2 | E20: 08:54 | F20: 20:09 | G20: 0.46875 | H20: 0.375 | I20: =MAX(H20-IF(R20="",0,R20),0) -> 0.375 | J20: =IF(G20>I20,G20-I20,0) -> 0.09375 | K20: =IF(I20>G20,I20-G20,0) -> 0 | L20: 0 | M20: 0 | N20: 0 | O20: 00:00 | P20: ---
B21: یکشنبه | C21: 1405/02/13 | D21: 2 | E21: 08:37 | F21: 20:29 | G21: 0.49444444 | H21: 0.375 | I21: =MAX(H21-IF(R21="",0,R21),0) -> 0.375 | J21: =IF(G21>I21,G21-I21,0) -> 0.11944444 | K21: =IF(I21>G21,I21-G21,0) -> 0 | L21: 0 | M21: 0 | N21: 0 | O21: 00:00 | P21: ---
B22: دوشنبه | C22: 1405/02/14 | D22: 2 | E22: 08:36 | F22: 17:40 | G22: 0.37777778 | H22: 0.375 | I22: =MAX(H22-IF(R22="",0,R22),0) -> 0.375 | J22: =IF(G22>I22,G22-I22,0) -> 0.0027777778 | K22: =IF(I22>G22,I22-G22,0) -> 0 | L22: 0 | M22: 0 | N22: 0 | O22: 00:00 | P22: ---
B23: سه‌شنبه | C23: 1405/02/15 | D23: 2 | E23: 09:19 | F23: 18:50 | G23: 0.39652778 | H23: 0.375 | I23: =MAX(H23-IF(R23="",0,R23),0) -> 0.375 | J23: =IF(G23>I23,G23-I23,0) -> 0.021527778 | K23: =IF(I23>G23,I23-G23,0) -> 0 | L23: 0 | M23: 0 | N23: 0 | O23: 00:00 | P23: ---
B24: چهارشنبه | C24: 1405/02/16 | D24: 2 | E24: 08:47 | F24: 20:00 | G24: 0.46736111 | H24: 0.33333333 | I24: =MAX(H24-IF(R24="",0,R24),0) -> 0.33333333 | J24: =IF(G24>I24,G24-I24,0) -> 0.13402778 | K24: =IF(I24>G24,I24-G24,0) -> 0 | L24: 0 | M24: 0 | N24: 0 | O24: 00:00 | P24: ---
B25: پنجشنبه | C25: 1405/02/17 | E25: ---- | F25: ---- | G25: 0 | H25: 0 | I25: =MAX(H25-IF(R25="",0,R25),0) -> 0 | J25: 0 | K25: 0 | L25: 0 | M25: 0 | N25: 0 | O25: 00:00 | P25: ---
B26: جمعه | C26: 1405/02/18 | E26: ---- | F26: ---- | G26: 0 | H26: 0 | I26: 0 | J26: 0 | K26: 0 | L26: 0 | M26: 0 | N26: 0 | O26: 00:00 | P26: ---
B27: شنبه | C27: 1405/02/19 | E27: ---- | F27: ---- | G27: 0 | H27: 0.375 | I27: 0 | J27: =IF(G27>I27,G27-I27,0) -> 0 | K27: =IF(I27>G27,I27-G27,0) -> 0 | L27: 0 | M27: 0 | N27: 0 | O27: 00:00 | P27: --- | Q27: 1
B28: یکشنبه | C28: 1405/02/20 | D28: 2 | E28: 08:17 | F28: 18:04 | G28: 0.40763889 | H28: 0.375 | I28: =MAX(H28-IF(R28="",0,R28),0) -> 0.375 | J28: =IF(G28>I28,G28-I28,0) -> 0.032638889 | K28: =IF(I28>G28,I28-G28,0) -> 0 | L28: 0 | M28: 0 | N28: 0 | O28: 00:00 | P28: ---
B29: دوشنبه | C29: 1405/02/21 | D29: 2 | E29: 08:24 | F29: 19:29 | G29: 0.46180556 | H29: 0.375 | I29: =MAX(H29-IF(R29="",0,R29),0) -> 0.375 | J29: =IF(G29>I29,G29-I29,0) -> 0.086805556 | K29: =IF(I29>G29,I29-G29,0) -> 0 | L29: 0 | M29: 0 | N29: 0 | O29: 00:00 | P29: ---
B30: سه‌شنبه | C30: 1405/02/22 | D30: 2 | E30: 08:11 | F30: 20:29 | G30: 0.5125 | H30: 0.375 | I30: =MAX(H30-IF(R30="",0,R30),0) -> 0.375 | J30: =IF(G30>I30,G30-I30,0) -> 0.1375 | K30: =IF(I30>G30,I30-G30,0) -> 0 | L30: 0 | M30: 0 | N30: 0 | O30: 00:00 | P30: ---
B31: چهارشنبه | C31: 1405/02/23 | E31: ---- | F31: ---- | G31: 0 | H31: 0.33333333 | I31: 0 | J31: =IF(G31>I31,G31-I31,0) -> 0 | K31: =IF(I31>G31,I31-G31,0) -> 0 | L31: 0 | M31: 0 | N31: 0 | O31: 00:00 | P31: --- | Q31: 1
B32: پنجشنبه | C32: 1405/02/24 | E32: ---- | F32: ---- | G32: 0 | H32: 0 | I32: =MAX(H32-IF(R32="",0,R32),0) -> 0 | J32: 0 | K32: 0 | L32: 0 | M32: 0 | N32: 0 | O32: 00:00 | P32: ---
B33: جمعه | C33: 1405/02/25 | E33: ---- | F33: ---- | G33: 0 | H33: 0 | I33: 0 | J33: 0 | K33: 0 | L33: 0 | M33: 0 | N33: 0 | O33: 00:00 | P33: ---
B34: جمع | D34: =SUM(D3:D33) -> 38 | G34: =SUM(G3:G33) -> 7.9104167 | H34: =SUM(H3:H33) -> 7.6666667 | I34: =SUM(I3:I33) -> 6.7083333 | J34: =SUM(J3:J33) -> 1.2020833 | K34: =SUM(K3:K33) -> 0 | L34: =SUM(L3:L33) -> 0 | M34: =SUM(M3:M33) -> 0 | N34: =SUM(N3:N33) -> 0 | Q34: =SUM(Q3:Q33) -> 2 | R34: =SUM(R3:R33) -> 0.25 | S34: =SUM(S3:S33) -> 0
H36: =IF(J34>=K34, J34-K34, 0) -> 1.2020833 | I36: اضافه کار واقعی
H37: =IF(K34<=J34, M34, IF(K34<=J34+M34, J34+M34-K34, 0)) -> 0 | I37: تعطیل کار واقعی
H38: =L34 -> 0 | I38: جمعه کاری
H39: =N34 -> 0 | I39: شبکاری
H40: =IF(K34>J34+M34, K34-J34-M34, 0) -> 0 | I40: کسرکار

Sheet محمدصابر نیک نام
A1: شرکت توسعه کارآفرینی سوره کارکرد اردیبهشت 1405-محمدصابر نیک نام
B2: روز | C2: تاریخ | D2: تعداد تردد | E2: اولین ورود | F2: آخرین خروج | G2: کارکرد | H2: کارکرد موظفی | I2: کارکرد موظف پس از کسر مرخصی | J2: اضافه کار | K2: کسرکار | L2: جمعه کاری | M2: تعطیل کاری | N2: شب کاری | O2: مرخصی | P2: نوع مرخصی | Q2: مرخصی استحقاقی | R2: مرخصی ساعتی | S2: مرخصی استعلاجی
B3: چهارشنبه | C3: 1405/01/26 | D3: 2 | E3: 10:45 | F3: 21:00 | G3: 0.42708333 | H3: 0.33333333 | I3: =IF(Q3<>"",IF(Q3>0,0,MAX(H3-IF(R3="",0,R3),0)),MAX(H3-IF(R3="",0,R3),0)) -> 0.33333333 | J3: =IF(G3>I3,G3-I3,0) -> 0.09375 | K3: =IF(I3>G3,I3-G3,0) -> 0 | L3: 0 | M3: 0 | N3: 0 | O3: 00:00 | P3: ---
B4: پنجشنبه | C4: 1405/01/27 | E4: ---- | F4: ---- | G4: 0 | H4: 0 | I4: =IF(Q4<>"",IF(Q4>0,0,MAX(H4-IF(R4="",0,R4),0)),MAX(H4-IF(R4="",0,R4),0)) -> 0 | J4: 0 | K4: 0 | L4: 0 | M4: 0 | N4: 0 | O4: 00:00 | P4: ---
B5: جمعه | C5: 1405/01/28 | E5: ---- | F5: ---- | G5: 0 | H5: 0 | I5: 0 | J5: 0 | K5: 0 | L5: 0 | M5: 0 | N5: 0 | O5: 00:00 | P5: ---
B6: شنبه | C6: 1405/01/29 | D6: 2 | E6: 08:45 | F6: 21:30 | G6: 0.53125 | H6: 0.375 | I6: =IF(Q6<>"",IF(Q6>0,0,MAX(H6-IF(R6="",0,R6),0)),MAX(H6-IF(R6="",0,R6),0)) -> 0.375 | J6: =IF(G6>I6,G6-I6,0) -> 0.15625 | K6: =IF(I6>G6,I6-G6,0) -> 0 | L6: 0 | M6: 0 | N6: 0 | O6: 00:00 | P6: ---
B7: یکشنبه | C7: 1405/01/30 | D7: 2 | E7: 09:30 | F7: 21:00 | G7: 0.47916667 | H7: 0.375 | I7: =IF(Q7<>"",IF(Q7>0,0,MAX(H7-IF(R7="",0,R7),0)),MAX(H7-IF(R7="",0,R7),0)) -> 0.375 | J7: =IF(G7>I7,G7-I7,0) -> 0.10416667 | K7: =IF(I7>G7,I7-G7,0) -> 0 | L7: 0 | M7: 0 | N7: 0 | O7: 00:00 | P7: ---
B8: دوشنبه | C8: 1405/01/31 | D8: 2 | E8: 09:58 | F8: 16:41 | G8: 0.27986111 | H8: 0.375 | I8: =IF(Q8<>"",IF(Q8>0,0,MAX(H8-IF(R8="",0,R8),0)),MAX(H8-IF(R8="",0,R8),0)) -> 0.375 | J8: =IF(G8>I8,G8-I8,0) -> 0 | K8: =IF(I8>G8,I8-G8,0) -> 0.095138889 | L8: 0 | M8: 0 | N8: 0 | O8: 00:00 | P8: ---
B9: سه‌شنبه | C9: 1405/02/01 | D9: 2 | E9: 09:00 | F9: 21:20 | G9: 0.51388889 | H9: 0.375 | I9: =IF(Q9<>"",IF(Q9>0,0,MAX(H9-IF(R9="",0,R9),0)),MAX(H9-IF(R9="",0,R9),0)) -> 0.375 | J9: =IF(G9>I9,G9-I9,0) -> 0.13888889 | K9: =IF(I9>G9,I9-G9,0) -> 0 | L9: 0 | M9: 0 | N9: 0 | O9: 00:00 | P9: ---
B10: چهارشنبه | C10: 1405/02/02 | D10: 2 | E10: 09:43 | F10: 19:15 | G10: 0.39722222 | H10: 0.33333333 | I10: =IF(Q10<>"",IF(Q10>0,0,MAX(H10-IF(R10="",0,R10),0)),MAX(H10-IF(R10="",0,R10),0)) -> 0.33333333 | J10: =IF(G10>I10,G10-I10,0) -> 0.063888889 | K10: =IF(I10>G10,I10-G10,0) -> 0 | L10: 0 | M10: 0 | N10: 0 | O10: 00:00 | P10: ---
B11: پنجشنبه | C11: 1405/02/03 | D11: 2 | E11: 11:00 | F11: 15:00 | G11: 0.16666667 | H11: 0 | I11: =IF(Q11<>"",IF(Q11>0,0,MAX(H11-IF(R11="",0,R11),0)),MAX(H11-IF(R11="",0,R11),0)) -> 0 | J11: 0 | K11: 0 | L11: 0 | M11: 0.16666667 | N11: 0 | O11: 00:00 | P11: ---
B12: جمعه | C12: 1405/02/04 | E12: ---- | F12: ---- | G12: 0 | H12: 0 | I12: 0 | J12: 0 | K12: 0 | L12: 0 | M12: 0 | N12: 0 | O12: 00:00 | P12: ---
B13: شنبه | C13: 1405/02/05 | D13: 2 | E13: 09:40 | F13: 22:05 | G13: 0.51736111 | H13: 0.375 | I13: =IF(Q13<>"",IF(Q13>0,0,MAX(H13-IF(R13="",0,R13),0)),MAX(H13-IF(R13="",0,R13),0)) -> 0.375 | J13: =IF(G13>I13,G13-I13,0) -> 0.14236111 | K13: =IF(I13>G13,I13-G13,0) -> 0 | L13: 0 | M13: 0 | N13: 0 | O13: 00:00 | P13: ---
B14: یکشنبه | C14: 1405/02/06 | D14: 2 | E14: 11:56 | F14: 20:30 | G14: 0.35694444 | H14: 0.375 | I14: =IF(Q14<>"",IF(Q14>0,0,MAX(H14-IF(R14="",0,R14),0)),MAX(H14-IF(R14="",0,R14),0)) -> 0.375 | J14: =IF(G14>I14,G14-I14,0) -> 0 | K14: =IF(I14>G14,I14-G14,0) -> 0.018055556 | L14: 0 | M14: 0 | N14: 0 | O14: 00:00 | P14: ---
B15: دوشنبه | C15: 1405/02/07 | D15: 2 | E15: 10:04 | F15: 20:10 | G15: 0.42083333 | H15: 0.375 | I15: =IF(Q15<>"",IF(Q15>0,0,MAX(H15-IF(R15="",0,R15),0)),MAX(H15-IF(R15="",0,R15),0)) -> 0.375 | J15: =IF(G15>I15,G15-I15,0) -> 0.045833333 | K15: =IF(I15>G15,I15-G15,0) -> 0 | L15: 0 | M15: 0 | N15: 0 | O15: 00:00 | P15: ---
B16: سه‌شنبه | C16: 1405/02/08 | D16: 2 | E16: 10:00 | F16: 20:36 | G16: 0.44166667 | H16: 0.375 | I16: =IF(Q16<>"",IF(Q16>0,0,MAX(H16-IF(R16="",0,R16),0)),MAX(H16-IF(R16="",0,R16),0)) -> 0.375 | J16: =IF(G16>I16,G16-I16,0) -> 0.066666667 | K16: =IF(I16>G16,I16-G16,0) -> 0 | L16: 0 | M16: 0 | N16: 0 | O16: 00:00 | P16: ---
B17: چهارشنبه | C17: 1405/02/09 | D17: 4 | E17: 12:20 | F17: 20:32 | G17: 0.34166667 | H17: 0.33333333 | I17: =IF(Q17<>"",IF(Q17>0,0,MAX(H17-IF(R17="",0,R17),0)),MAX(H17-IF(R17="",0,R17),0)) -> 0.33333333 | J17: =IF(G17>I17,G17-I17,0) -> 0.0083333333 | K17: =IF(I17>G17,I17-G17,0) -> 0 | L17: 0 | M17: 0 | N17: 0 | O17: 00:00 | P17: ---
B18: پنجشنبه | C18: 1405/02/10 | E18: ---- | F18: ---- | G18: 0 | H18: 0 | I18: =IF(Q18<>"",IF(Q18>0,0,MAX(H18-IF(R18="",0,R18),0)),MAX(H18-IF(R18="",0,R18),0)) -> 0 | J18: 0 | K18: 0 | L18: 0 | M18: 0 | N18: 0 | O18: 00:00 | P18: ---
B19: جمعه | C19: 1405/02/11 | E19: ---- | F19: ---- | G19: 0 | H19: 0 | I19: 0 | J19: 0 | K19: 0 | L19: 0 | M19: 0 | N19: 0 | O19: 00:00 | P19: ---
B20: شنبه | C20: 1405/02/12 | D20: 2 | E20: 11:01 | F20: 22:13 | G20: 0.46666667 | H20: 0.375 | I20: =IF(Q20<>"",IF(Q20>0,0,MAX(H20-IF(R20="",0,R20),0)),MAX(H20-IF(R20="",0,R20),0)) -> 0.375 | J20: =IF(G20>I20,G20-I20,0) -> 0.091666667 | K20: =IF(I20>G20,I20-G20,0) -> 0 | L20: 0 | M20: 0 | N20: 0 | O20: 00:00 | P20: ---
B21: یکشنبه | C21: 1405/02/13 | D21: 2 | E21: 10:20 | F21: 21:00 | G21: 0.44444444 | H21: 0.375 | I21: =IF(Q21<>"",IF(Q21>0,0,MAX(H21-IF(R21="",0,R21),0)),MAX(H21-IF(R21="",0,R21),0)) -> 0.375 | J21: =IF(G21>I21,G21-I21,0) -> 0.069444444 | K21: =IF(I21>G21,I21-G21,0) -> 0 | L21: 0 | M21: 0 | N21: 0 | O21: 00:00 | P21: ---
B22: دوشنبه | C22: 1405/02/14 | D22: 2 | E22: 07:30 | F22: 19:30 | G22: 0.5 | H22: 0.375 | I22: =IF(Q22<>"",IF(Q22>0,0,MAX(H22-IF(R22="",0,R22),0)),MAX(H22-IF(R22="",0,R22),0)) -> 0.375 | J22: =IF(G22>I22,G22-I22,0) -> 0.125 | K22: =IF(I22>G22,I22-G22,0) -> 0 | L22: 0 | M22: 0 | N22: 0 | O22: 00:00 | P22: ---
B23: سه‌شنبه | C23: 1405/02/15 | D23: 2 | E23: 10:00 | F23: 21:00 | G23: 0.45833333 | H23: 0.375 | I23: =IF(Q23<>"",IF(Q23>0,0,MAX(H23-IF(R23="",0,R23),0)),MAX(H23-IF(R23="",0,R23),0)) -> 0.375 | J23: =IF(G23>I23,G23-I23,0) -> 0.083333333 | K23: =IF(I23>G23,I23-G23,0) -> 0 | L23: 0 | M23: 0 | N23: 0 | O23: 00:00 | P23: ---
B24: چهارشنبه | C24: 1405/02/16 | D24: 2 | E24: 07:11 | F24: 21:00 | G24: 0.57569444 | H24: 0.33333333 | I24: =IF(Q24<>"",IF(Q24>0,0,MAX(H24-IF(R24="",0,R24),0)),MAX(H24-IF(R24="",0,R24),0)) -> 0.33333333 | J24: =IF(G24>I24,G24-I24,0) -> 0.24236111 | K24: =IF(I24>G24,I24-G24,0) -> 0 | L24: 0 | M24: 0 | N24: 0 | O24: 00:00 | P24: ---
B25: پنجشنبه | C25: 1405/02/17 | E25: ---- | F25: ---- | G25: 0 | H25: 0 | I25: =IF(Q25<>"",IF(Q25>0,0,MAX(H25-IF(R25="",0,R25),0)),MAX(H25-IF(R25="",0,R25),0)) -> 0 | J25: 0 | K25: 0 | L25: 0 | M25: 0 | N25: 0 | O25: 00:00 | P25: ---
B26: جمعه | C26: 1405/02/18 | E26: ---- | F26: ---- | G26: 0 | H26: 0 | I26: 0 | J26: 0 | K26: 0 | L26: 0 | M26: 0 | N26: 0 | O26: 00:00 | P26: ---
B27: شنبه | C27: 1405/02/19 | D27: 2 | E27: 09:47 | F27: 16:30 | G27: 0.27986111 | H27: 0.375 | I27: =IF(Q27<>"",IF(Q27>0,0,MAX(H27-IF(R27="",0,R27),0)),MAX(H27-IF(R27="",0,R27),0)) -> 0.375 | J27: =IF(G27>I27,G27-I27,0) -> 0 | K27: =IF(I27>G27,I27-G27,0) -> 0.095138889 | L27: 0 | M27: 0 | N27: 0 | O27: 00:00 | P27: ---
B28: یکشنبه | C28: 1405/02/20 | D28: 2 | E28: 10:30 | F28: 20:00 | G28: 0.39583333 | H28: 0.375 | I28: =IF(Q28<>"",IF(Q28>0,0,MAX(H28-IF(R28="",0,R28),0)),MAX(H28-IF(R28="",0,R28),0)) -> 0.375 | J28: =IF(G28>I28,G28-I28,0) -> 0.020833333 | K28: =IF(I28>G28,I28-G28,0) -> 0 | L28: 0 | M28: 0 | N28: 0 | O28: 00:00 | P28: ---
B29: دوشنبه | C29: 1405/02/21 | D29: 2 | E29: 09:30 | F29: 20:10 | G29: 0.44444444 | H29: 0.375 | I29: =IF(Q29<>"",IF(Q29>0,0,MAX(H29-IF(R29="",0,R29),0)),MAX(H29-IF(R29="",0,R29),0)) -> 0.375 | J29: =IF(G29>I29,G29-I29,0) -> 0.069444444 | K29: =IF(I29>G29,I29-G29,0) -> 0 | L29: 0 | M29: 0 | N29: 0 | O29: 00:00 | P29: ---
B30: سه‌شنبه | C30: 1405/02/22 | D30: 2 | E30: 09:11 | F30: 21:55 | G30: 0.53055556 | H30: 0.375 | I30: =IF(Q30<>"",IF(Q30>0,0,MAX(H30-IF(R30="",0,R30),0)),MAX(H30-IF(R30="",0,R30),0)) -> 0.375 | J30: =IF(G30>I30,G30-I30,0) -> 0.15555556 | K30: =IF(I30>G30,I30-G30,0) -> 0 | L30: 0 | M30: 0 | N30: 0 | O30: 00:00 | P30: ---
B31: چهارشنبه | C31: 1405/02/23 | D31: 2 | E31: 09:16 | F31: 20:00 | G31: 0.44722222 | H31: 0.33333333 | I31: =IF(Q31<>"",IF(Q31>0,0,MAX(H31-IF(R31="",0,R31),0)),MAX(H31-IF(R31="",0,R31),0)) -> 0.33333333 | J31: =IF(G31>I31,G31-I31,0) -> 0.11388889 | K31: =IF(I31>G31,I31-G31,0) -> 0 | L31: 0 | M31: 0 | N31: 0 | O31: 00:00 | P31: ---
B32: پنجشنبه | C32: 1405/02/24 | E32: ---- | F32: ---- | G32: 0 | H32: 0 | I32: =IF(Q32<>"",IF(Q32>0,0,MAX(H32-IF(R32="",0,R32),0)),MAX(H32-IF(R32="",0,R32),0)) -> 0 | J32: 0 | K32: 0 | L32: 0 | M32: 0 | N32: 0 | O32: 00:00 | P32: ---
B33: جمعه | C33: 1405/02/25 | E33: ---- | F33: ---- | G33: 0 | H33: 0 | I33: 0 | J33: 0 | K33: 0 | L33: 0 | M33: 0 | N33: 0 | O33: 00:00 | P33: ---
B34: جمع | D34: =SUM(D3:D33) -> 46 | G34: =SUM(G3:G33) -> 9.4166667 | H34: =SUM(H3:H33) -> 7.6666667 | I34: =SUM(I3:I33) -> 7.6666667 | J34: =SUM(J3:J33) -> 1.7916667 | K34: =SUM(K3:K33) -> 0.20833333 | L34: =SUM(L3:L33) -> 0 | M34: =SUM(M3:M33) -> 0.16666667 | N34: =SUM(N3:N33) -> 0 | Q34: =SUM(Q3:Q33) -> 0 | R34: =SUM(R3:R33) -> 0 | S34: =SUM(S3:S33) -> 0
H35: 1.25 | I35: اضافه کار واقعی
H36: =IF(J34>=K34,J34-K34,0) -> 1.5833333 | I36: اضافه کار واقعی
H37: =IF(K34<=J34,M34,IF(K34<=J34+M34,J34+M34-K34,0)) -> 0.16666667 | I37: تعطیل کار واقعی
H38: =L34 -> 0 | I38: جمعه کاری
H39: =N34 -> 0 | I39: شبکاری
H40: =IF(K34>J34+M34,K34-J34-M34,0) -> 0 | I40: کسرکار کل

Sheet سمیرا نورشرق
A1: شرکت توسعه کارآفرینی سوره کارکرد اردیبهشت 1405-سمیرا نورشرق
B2: روز | C2: تاریخ | D2: تعداد تردد | E2: اولین ورود | F2: آخرین خروج | G2: کارکرد | H2: کارکرد موظفی | I2: کارکرد موظف پس از کسر مرخصی | J2: اضافه کار | K2: کسرکار | L2: جمعه کاری | M2: تعطیل کاری | N2: شب کاری | O2: مرخصی | P2: نوع مرخصی | Q2: مرخصی استحقاقی | R2: مرخصی ساعتی | S2: مرخصی استعلاجی
B3: چهارشنبه | C3: 1405/01/26 | D3: 2 | E3: 09:48 | F3: 19:04 | G3: 0.38611111 | H3: 0.33333333 | I3: =MAX(H3-IF(R3="",0,R3),0) -> 0.25833333 | J3: =IF(G3>I3,G3-I3,0) -> 0.12777778 | K3: =IF(I3>G3,I3-G3,0) -> 0 | L3: 0 | M3: 0 | N3: 0 | O3: 00:00 | P3: --- | R3: 0.075
B4: پنجشنبه | C4: 1405/01/27 | E4: ---- | F4: ---- | G4: 0 | H4: 0 | I4: =MAX(H4-IF(R4="",0,R4),0) -> 0 | J4: 0 | K4: 0 | L4: 0 | M4: 0 | N4: 0 | O4: 00:00 | P4: ---
B5: جمعه | C5: 1405/01/28 | E5: ---- | F5: ---- | G5: 0 | H5: 0 | I5: 0 | J5: 0 | K5: 0 | L5: 0 | M5: 0 | N5: 0 | O5: 00:00 | P5: ---
B6: شنبه | C6: 1405/01/29 | D6: 2 | E6: 08:58 | F6: 18:23 | G6: 0.39236111 | H6: 0.375 | I6: =MAX(H6-IF(R6="",0,R6),0) -> 0.375 | J6: =IF(G6>I6,G6-I6,0) -> 0.017361111 | K6: =IF(I6>G6,I6-G6,0) -> 0 | L6: 0 | M6: 0 | N6: 0 | O6: 00:00 | P6: ---
B7: یکشنبه | C7: 1405/01/30 | D7: 2 | E7: 09:05 | F7: 19:00 | G7: 0.41319444 | H7: 0.375 | I7: =MAX(H7-IF(R7="",0,R7),0) -> 0.375 | J7: =IF(G7>I7,G7-I7,0) -> 0.038194444 | K7: =IF(I7>G7,I7-G7,0) -> 0 | L7: 0 | M7: 0 | N7: 0 | O7: 00:00 | P7: ---
B8: دوشنبه | C8: 1405/01/31 | D8: 2 | E8: 08:44 | F8: 19:25 | G8: 0.44513889 | H8: 0.375 | I8: =MAX(H8-IF(R8="",0,R8),0) -> 0.375 | J8: =IF(G8>I8,G8-I8,0) -> 0.070138889 | K8: =IF(I8>G8,I8-G8,0) -> 0 | L8: 0 | M8: 0 | N8: 0 | O8: 00:00 | P8: ---
B9: سه‌شنبه | C9: 1405/02/01 | D9: 2 | E9: 08:49 | F9: 19:10 | G9: 0.43125 | H9: 0.375 | I9: =MAX(H9-IF(R9="",0,R9),0) -> 0.375 | J9: =IF(G9>I9,G9-I9,0) -> 0.05625 | K9: =IF(I9>G9,I9-G9,0) -> 0 | L9: 0 | M9: 0 | N9: 0 | O9: 00:00 | P9: ---
B10: چهارشنبه | C10: 1405/02/02 | D10: 2 | E10: 08:58 | F10: 18:30 | G10: 0.39722222 | H10: 0.33333333 | I10: =MAX(H10-IF(R10="",0,R10),0) -> 0.33333333 | J10: =IF(G10>I10,G10-I10,0) -> 0.063888889 | K10: =IF(I10>G10,I10-G10,0) -> 0 | L10: 0 | M10: 0 | N10: 0 | O10: 00:00 | P10: ---
B11: پنجشنبه | C11: 1405/02/03 | E11: ---- | F11: ---- | G11: 0 | H11: 0 | I11: =MAX(H11-IF(R11="",0,R11),0) -> 0 | J11: 0 | K11: 0 | L11: 0 | M11: 0 | N11: 0 | O11: 00:00 | P11: ---
B12: جمعه | C12: 1405/02/04 | E12: ---- | F12: ---- | G12: 0 | H12: 0 | I12: 0 | J12: 0 | K12: 0 | L12: 0 | M12: 0 | N12: 0 | O12: 00:00 | P12: ---
B13: شنبه | C13: 1405/02/05 | D13: 2 | E13: 09:06 | F13: 20:57 | G13: 0.49375 | H13: 0.375 | I13: =MAX(H13-IF(R13="",0,R13),0) -> 0.375 | J13: =IF(G13>I13,G13-I13,0) -> 0.11875 | K13: =IF(I13>G13,I13-G13,0) -> 0 | L13: 0 | M13: 0 | N13: 0 | O13: 00:00 | P13: ---
B14: یکشنبه | C14: 1405/02/06 | D14: 2 | E14: 09:09 | F14: 18:45 | G14: 0.4 | H14: 0.375 | I14: =MAX(H14-IF(R14="",0,R14),0) -> 0.375 | J14: =IF(G14>I14,G14-I14,0) -> 0.025 | K14: =IF(I14>G14,I14-G14,0) -> 0 | L14: 0 | M14: 0 | N14: 0 | O14: 00:00 | P14: ---
B15: دوشنبه | C15: 1405/02/07 | D15: 2 | E15: 09:09 | F15: 18:10 | G15: 0.37569444 | H15: 0.375 | I15: =MAX(H15-IF(R15="",0,R15),0) -> 0.375 | J15: =IF(G15>I15,G15-I15,0) -> 0.00069444444 | K15: =IF(I15>G15,I15-G15,0) -> 0 | L15: 0 | M15: 0 | N15: 0 | O15: 00:00 | P15: ---
B16: سه‌شنبه | C16: 1405/02/08 | D16: 2 | E16: 08:59 | F16: 16:24 | G16: 0.30902778 | H16: 0.375 | I16: =MAX(H16-IF(R16="",0,R16),0) -> 0.35 | J16: =IF(G16>I16,G16-I16,0) -> 0 | K16: =IF(I16>G16,I16-G16,0) -> 0.040972222 | L16: 0 | M16: 0 | N16: 0 | O16: 00:00 | P16: --- | R16: 0.025
B17: چهارشنبه | C17: 1405/02/09 | D17: 2 | E17: 09:21 | F17: 16:41 | G17: 0.30555556 | H17: 0.33333333 | I17: =MAX(H17-IF(R17="",0,R17),0) -> 0.27708333 | J17: =IF(G17>I17,G17-I17,0) -> 0.028472222 | K17: =IF(I17>G17,I17-G17,0) -> 0 | L17: 0 | M17: 0 | N17: 0 | O17: 00:00 | P17: --- | R17: 0.05625
B18: پنجشنبه | C18: 1405/02/10 | E18: ---- | F18: ---- | G18: 0 | H18: 0 | I18: =MAX(H18-IF(R18="",0,R18),0) -> 0 | J18: 0 | K18: 0 | L18: 0 | M18: 0 | N18: 0 | O18: 00:00 | P18: ---
B19: جمعه | C19: 1405/02/11 | E19: ---- | F19: ---- | G19: 0 | H19: 0 | I19: 0 | J19: 0 | K19: 0 | L19: 0 | M19: 0 | N19: 0 | O19: 00:00 | P19: ---
B20: شنبه | C20: 1405/02/12 | D20: 2 | E20: 09:11 | F20: 16:19 | G20: 0.29722222 | H20: 0.375 | I20: =MAX(H20-IF(R20="",0,R20),0) -> 0.375 | J20: =IF(G20>I20,G20-I20,0) -> 0 | K20: =IF(I20>G20,I20-G20,0) -> 0.077777778 | L20: 0 | M20: 0 | N20: 0 | O20: 00:00 | P20: ---
B21: یکشنبه | C21: 1405/02/13 | D21: 2 | E21: 09:21 | F21: 19:31 | G21: 0.42361111 | H21: 0.375 | I21: =MAX(H21-IF(R21="",0,R21),0) -> 0.375 | J21: =IF(G21>I21,G21-I21,0) -> 0.048611111 | K21: =IF(I21>G21,I21-G21,0) -> 0 | L21: 0 | M21: 0 | N21: 0 | O21: 00:00 | P21: ---
B22: دوشنبه | C22: 1405/02/14 | D22: 2 | E22: 08:42 | F22: 19:18 | G22: 0.44166667 | H22: 0.375 | I22: =MAX(H22-IF(R22="",0,R22),0) -> 0.375 | J22: =IF(G22>I22,G22-I22,0) -> 0.066666667 | K22: =IF(I22>G22,I22-G22,0) -> 0 | L22: 0 | M22: 0 | N22: 0 | O22: 00:00 | P22: ---
B23: سه‌شنبه | C23: 1405/02/15 | D23: 2 | E23: 10:00 | F23: 20:32 | G23: 0.43888889 | H23: 0.375 | I23: =MAX(H23-IF(R23="",0,R23),0) -> 0.29166667 | J23: =IF(G23>I23,G23-I23,0) -> 0.14722222 | K23: =IF(I23>G23,I23-G23,0) -> 0 | L23: 0 | M23: 0 | N23: 0 | O23: 00:00 | P23: --- | R23: 0.083333333
B24: چهارشنبه | C24: 1405/02/16 | D24: 2 | E24: 08:25 | F24: 20:52 | G24: 0.51875 | H24: 0.33333333 | I24: =MAX(H24-IF(R24="",0,R24),0) -> 0.33333333 | J24: =IF(G24>I24,G24-I24,0) -> 0.18541667 | K24: =IF(I24>G24,I24-G24,0) -> 0 | L24: 0 | M24: 0 | N24: 0 | O24: 00:00 | P24: ---
B25: پنجشنبه | C25: 1405/02/17 | E25: ---- | F25: ---- | G25: 0 | H25: 0 | I25: =MAX(H25-IF(R25="",0,R25),0) -> 0 | J25: 0 | K25: 0 | L25: 0 | M25: 0 | N25: 0 | O25: 00:00 | P25: ---
B26: جمعه | C26: 1405/02/18 | E26: ---- | F26: ---- | G26: 0 | H26: 0 | I26: 0 | J26: 0 | K26: 0 | L26: 0 | M26: 0 | N26: 0 | O26: 00:00 | P26: ---
B27: شنبه | C27: 1405/02/19 | D27: 2 | E27: 08:29 | F27: 18:23 | G27: 0.4125 | H27: 0.375 | I27: =MAX(H27-IF(R27="",0,R27),0) -> 0.375 | J27: =IF(G27>I27,G27-I27,0) -> 0.0375 | K27: =IF(I27>G27,I27-G27,0) -> 0 | L27: 0 | M27: 0 | N27: 0 | O27: 00:00 | P27: ---
B28: یکشنبه | C28: 1405/02/20 | D28: 2 | E28: 09:23 | F28: 19:42 | G28: 0.42986111 | H28: 0.375 | I28: =MAX(H28-IF(R28="",0,R28),0) -> 0.375 | J28: =IF(G28>I28,G28-I28,0) -> 0.054861111 | K28: =IF(I28>G28,I28-G28,0) -> 0 | L28: 0 | M28: 0 | N28: 0 | O28: 00:00 | P28: ---
B29: دوشنبه | C29: 1405/02/21 | D29: 2 | E29: 08:15 | F29: 20:32 | G29: 0.51180556 | H29: 0.375 | I29: =MAX(H29-IF(R29="",0,R29),0) -> 0.375 | J29: =IF(G29>I29,G29-I29,0) -> 0.13680556 | K29: =IF(I29>G29,I29-G29,0) -> 0 | L29: 0 | M29: 0 | N29: 0 | O29: 00:00 | P29: ---
B30: سه‌شنبه | C30: 1405/02/22 | D30: 2 | E30: 09:06 | F30: 19:27 | G30: 0.43125 | H30: 0.375 | I30: =MAX(H30-IF(R30="",0,R30),0) -> 0.375 | J30: =IF(G30>I30,G30-I30,0) -> 0.05625 | K30: =IF(I30>G30,I30-G30,0) -> 0 | L30: 0 | M30: 0 | N30: 0 | O30: 00:00 | P30: ---
B31: چهارشنبه | C31: 1405/02/23 | D31: 2 | E31: 09:30 | F31: 20:42 | G31: 0.46666667 | H31: 0.33333333 | I31: =MAX(H31-IF(R31="",0,R31),0) -> 0.33333333 | J31: =IF(G31>I31,G31-I31,0) -> 0.13333333 | K31: =IF(I31>G31,I31-G31,0) -> 0 | L31: 0 | M31: 0 | N31: 0 | O31: 00:00 | P31: ---
B32: پنجشنبه | C32: 1405/02/24 | E32: ---- | F32: ---- | G32: 0 | H32: 0 | I32: =MAX(H32-IF(R32="",0,R32),0) -> 0 | J32: 0 | K32: 0 | L32: 0 | M32: 0 | N32: 0 | O32: 00:00 | P32: ---
B33: جمعه | C33: 1405/02/25 | E33: ---- | F33: ---- | G33: 0 | H33: 0 | I33: 0 | J33: 0 | K33: 0 | L33: 0 | M33: 0 | N33: 0 | O33: 00:00 | P33: ---
B34: جمع | D34: =SUM(D3:D33) -> 42 | G34: =SUM(G3:G33) -> 8.7215278 | H34: =SUM(H3:H33) -> 7.6666667 | I34: =SUM(I3:I33) -> 7.4270833 | J34: =SUM(J3:J33) -> 1.4131944 | K34: =SUM(K3:K33) -> 0.11875 | L34: =SUM(L3:L33) -> 0 | M34: =SUM(M3:M33) -> 0 | N34: =SUM(N3:N33) -> 0 | Q34: =SUM(Q3:Q33) -> 0 | R34: =SUM(R3:R33) -> 0.23958333 | S34: =SUM(S3:S33) -> 0
H35: 1.25 | I35: اضافه کار واقعی
H36: =IF(J34>=K34, J34-K34, 0) -> 1.2944444 | I36: اضافه کار واقعی
H37: =IF(K34<=J34, M34, IF(K34<=J34+M34, J34+M34-K34, 0)) -> 0 | I37: تعطیل کار
H38: =L34 -> 0 | I38: جمعه کاری
H39: =N34 -> 0 | I39: شبکاری
H40: =IF(K34>J34+M34, K34-J34-M34, 0) -> 0 | I40: کسرکار

Sheet معروف فتحی
A1: شرکت توسعه کارآفرینی سوره کارکرد اردیبهشت 1405-معروف فتحی
B2: روز | C2: تاریخ | D2: تعداد تردد | E2: اولین ورود | F2: آخرین خروج | G2: کارکرد | H2: کارکرد موظفی | I2: کارکرد موظف پس از کسر مرخصی | J2: اضافه کار | K2: کسرکار | L2: جمعه کاری | M2: تعطیل کاری | N2: شب کاری | O2: مرخصی | P2: نوع مرخصی | Q2: مرخصی استحقاقی | R2: مرخصی ساعتی | S2: مرخصی استعلاجی
B3: چهارشنبه | C3: 1405/01/26 | D3: 2 | E3: 06:08 | F3: 20:45 | G3: 0.60902778 | H3: 0.33333333 | I3: =MAX(H3-IF(R3="",0,R3),0) -> 0.33333333 | J3: =IF(G3>I3,G3-I3,0) -> 0.27569444 | K3: =IF(I3>G3,I3-G3,0) -> 0 | L3: 0 | M3: 0 | N3: 0 | O3: 00:00 | P3: ---
B4: پنجشنبه | C4: 1405/01/27 | D4: 2 | E4: 06:04 | F4: 17:07 | G4: 0.46041667 | H4: 0 | I4: =MAX(H4-IF(R4="",0,R4),0) -> 0 | J4: 0 | K4: 0 | L4: 0 | M4: 0.46041667 | N4: 0 | O4: 00:00 | P4: ---
B5: جمعه | C5: 1405/01/28 | E5: ---- | F5: ---- | G5: 0 | H5: 0 | I5: 0 | J5: 0 | K5: 0 | L5: 0 | M5: 0 | N5: 0 | O5: 00:00 | P5: ---
B6: شنبه | C6: 1405/01/29 | D6: 2 | E6: 06:06 | F6: 19:38 | G6: 0.56388889 | H6: 0.375 | I6: =MAX(H6-IF(R6="",0,R6),0) -> 0.375 | J6: =IF(G6>I6,G6-I6,0) -> 0.18888889 | K6: =IF(I6>G6,I6-G6,0) -> 0 | L6: 0 | M6: 0 | N6: 0 | O6: 00:00 | P6: ---
B7: یکشنبه | C7: 1405/01/30 | D7: 2 | E7: 06:06 | F7: 19:36 | G7: 0.5625 | H7: 0.375 | I7: =MAX(H7-IF(R7="",0,R7),0) -> 0.375 | J7: =IF(G7>I7,G7-I7,0) -> 0.1875 | K7: =IF(I7>G7,I7-G7,0) -> 0 | L7: 0 | M7: 0 | N7: 0 | O7: 00:00 | P7: ---
B8: دوشنبه | C8: 1405/01/31 | D8: 2 | E8: 06:04 | F8: 19:39 | G8: 0.56597222 | H8: 0.375 | I8: =MAX(H8-IF(R8="",0,R8),0) -> 0.375 | J8: =IF(G8>I8,G8-I8,0) -> 0.19097222 | K8: =IF(I8>G8,I8-G8,0) -> 0 | L8: 0 | M8: 0 | N8: 0 | O8: 00:00 | P8: ---
B9: سه‌شنبه | C9: 1405/02/01 | D9: 2 | E9: 06:03 | F9: 19:33 | G9: 0.5625 | H9: 0.375 | I9: =MAX(H9-IF(R9="",0,R9),0) -> 0.375 | J9: =IF(G9>I9,G9-I9,0) -> 0.1875 | K9: =IF(I9>G9,I9-G9,0) -> 0 | L9: 0 | M9: 0 | N9: 0 | O9: 00:00 | P9: ---
B10: چهارشنبه | C10: 1405/02/02 | D10: 2 | E10: 06:04 | F10: 19:36 | G10: 0.56388889 | H10: 0.33333333 | I10: =MAX(H10-IF(R10="",0,R10),0) -> 0.33333333 | J10: =IF(G10>I10,G10-I10,0) -> 0.23055556 | K10: =IF(I10>G10,I10-G10,0) -> 0 | L10: 0 | M10: 0 | N10: 0 | O10: 00:00 | P10: ---
B11: پنجشنبه | C11: 1405/02/03 | D11: 2 | E11: 06:00 | F11: 14:42 | G11: 0.3625 | H11: 0 | I11: =MAX(H11-IF(R11="",0,R11),0) -> 0 | J11: 0 | K11: 0 | L11: 0 | M11: 0.3625 | N11: 0 | O11: 00:00 | P11: ---
B12: جمعه | C12: 1405/02/04 | E12: ---- | F12: ---- | G12: 0 | H12: 0 | I12: 0 | J12: 0 | K12: 0 | L12: 0 | M12: 0 | N12: 0 | O12: 00:00 | P12: ---
B13: شنبه | C13: 1405/02/05 | D13: 2 | E13: 06:05 | F13: 19:25 | G13: 0.55555556 | H13: 0.375 | I13: =MAX(H13-IF(R13="",0,R13),0) -> 0.375 | J13: =IF(G13>I13,G13-I13,0) -> 0.18055556 | K13: =IF(I13>G13,I13-G13,0) -> 0 | L13: 0 | M13: 0 | N13: 0 | O13: 00:00 | P13: ---
B14: یکشنبه | C14: 1405/02/06 | D14: 2 | E14: 06:05 | F14: 19:25 | G14: 0.55555556 | H14: 0.375 | I14: =MAX(H14-IF(R14="",0,R14),0) -> 0.375 | J14: =IF(G14>I14,G14-I14,0) -> 0.18055556 | K14: =IF(I14>G14,I14-G14,0) -> 0 | L14: 0 | M14: 0 | N14: 0 | O14: 00:00 | P14: ---
B15: دوشنبه | C15: 1405/02/07 | D15: 2 | E15: 06:04 | F15: 19:28 | G15: 0.55833333 | H15: 0.375 | I15: =MAX(H15-IF(R15="",0,R15),0) -> 0.375 | J15: =IF(G15>I15,G15-I15,0) -> 0.18333333 | K15: =IF(I15>G15,I15-G15,0) -> 0 | L15: 0 | M15: 0 | N15: 0 | O15: 00:00 | P15: ---
B16: سه‌شنبه | C16: 1405/02/08 | D16: 2 | E16: 06:02 | F16: 19:26 | G16: 0.55833333 | H16: 0.375 | I16: =MAX(H16-IF(R16="",0,R16),0) -> 0.375 | J16: =IF(G16>I16,G16-I16,0) -> 0.18333333 | K16: =IF(I16>G16,I16-G16,0) -> 0 | L16: 0 | M16: 0 | N16: 0 | O16: 00:00 | P16: ---
B17: چهارشنبه | C17: 1405/02/09 | D17: 2 | E17: 06:04 | F17: 19:32 | G17: 0.56111111 | H17: 0.33333333 | I17: =MAX(H17-IF(R17="",0,R17),0) -> 0.33333333 | J17: =IF(G17>I17,G17-I17,0) -> 0.22777778 | K17: =IF(I17>G17,I17-G17,0) -> 0 | L17: 0 | M17: 0 | N17: 0 | O17: 00:00 | P17: ---
B18: پنجشنبه | C18: 1405/02/10 | D18: 2 | E18: 06:00 | F18: 17:34 | G18: 0.48194444 | H18: 0 | I18: =MAX(H18-IF(R18="",0,R18),0) -> 0 | J18: 0 | K18: 0 | L18: 0 | M18: 0.48194444 | N18: 0 | O18: 00:00 | P18: ---
B19: جمعه | C19: 1405/02/11 | E19: ---- | F19: ---- | G19: 0 | H19: 0 | I19: 0 | J19: 0 | K19: 0 | L19: 0 | M19: 0 | N19: 0 | O19: 00:00 | P19: ---
B20: شنبه | C20: 1405/02/12 | D20: 2 | E20: 06:01 | F20: 20:01 | G20: 0.58333333 | H20: 0.375 | I20: =MAX(H20-IF(R20="",0,R20),0) -> 0.375 | J20: =IF(G20>I20,G20-I20,0) -> 0.20833333 | K20: =IF(I20>G20,I20-G20,0) -> 0 | L20: 0 | M20: 0 | N20: 0 | O20: 00:00 | P20: ---
B21: یکشنبه | C21: 1405/02/13 | D21: 2 | E21: 06:03 | F21: 18:27 | G21: 0.51666667 | H21: 0.375 | I21: =MAX(H21-IF(R21="",0,R21),0) -> 0.375 | J21: =IF(G21>I21,G21-I21,0) -> 0.14166667 | K21: =IF(I21>G21,I21-G21,0) -> 0 | L21: 0 | M21: 0 | N21: 0 | O21: 00:00 | P21: ---
B22: دوشنبه | C22: 1405/02/14 | D22: 2 | E22: 06:03 | F22: 19:33 | G22: 0.5625 | H22: 0.375 | I22: =MAX(H22-IF(R22="",0,R22),0) -> 0.375 | J22: =IF(G22>I22,G22-I22,0) -> 0.1875 | K22: =IF(I22>G22,I22-G22,0) -> 0 | L22: 0 | M22: 0 | N22: 0 | O22: 00:00 | P22: ---
B23: سه‌شنبه | C23: 1405/02/15 | D23: 2 | E23: 06:04 | F23: 19:32 | G23: 0.56111111 | H23: 0.375 | I23: =MAX(H23-IF(R23="",0,R23),0) -> 0.375 | J23: =IF(G23>I23,G23-I23,0) -> 0.18611111 | K23: =IF(I23>G23,I23-G23,0) -> 0 | L23: 0 | M23: 0 | N23: 0 | O23: 00:00 | P23: ---
B24: چهارشنبه | C24: 1405/02/16 | D24: 2 | E24: 06:05 | F24: 20:02 | G24: 0.58125 | H24: 0.33333333 | I24: =MAX(H24-IF(R24="",0,R24),0) -> 0.33333333 | J24: =IF(G24>I24,G24-I24,0) -> 0.24791667 | K24: =IF(I24>G24,I24-G24,0) -> 0 | L24: 0 | M24: 0 | N24: 0 | O24: 00:00 | P24: ---
B25: پنجشنبه | C25: 1405/02/17 | E25: ---- | F25: ---- | G25: 0 | H25: 0 | I25: =MAX(H25-IF(R25="",0,R25),0) -> 0 | J25: 0 | K25: 0 | L25: 0 | M25: 0 | N25: 0 | O25: 00:00 | P25: ---
B26: جمعه | C26: 1405/02/18 | E26: ---- | F26: ---- | G26: 0 | H26: 0 | I26: 0 | J26: 0 | K26: 0 | L26: 0 | M26: 0 | N26: 0 | O26: 00:00 | P26: ---
B27: شنبه | C27: 1405/02/19 | D27: 2 | E27: 06:02 | F27: 20:01 | G27: 0.58263889 | H27: 0.375 | I27: =MAX(H27-IF(R27="",0,R27),0) -> 0.375 | J27: =IF(G27>I27,G27-I27,0) -> 0.20763889 | K27: =IF(I27>G27,I27-G27,0) -> 0 | L27: 0 | M27: 0 | N27: 0 | O27: 00:00 | P27: ---
B28: یکشنبه | C28: 1405/02/20 | D28: 2 | E28: 06:03 | F28: 20:03 | G28: 0.58333333 | H28: 0.375 | I28: =MAX(H28-IF(R28="",0,R28),0) -> 0.375 | J28: =IF(G28>I28,G28-I28,0) -> 0.20833333 | K28: =IF(I28>G28,I28-G28,0) -> 0 | L28: 0 | M28: 0 | N28: 0 | O28: 00:00 | P28: ---
B29: دوشنبه | C29: 1405/02/21 | D29: 2 | E29: 06:06 | F29: 20:10 | G29: 0.58611111 | H29: 0.375 | I29: =MAX(H29-IF(R29="",0,R29),0) -> 0.375 | J29: =IF(G29>I29,G29-I29,0) -> 0.21111111 | K29: =IF(I29>G29,I29-G29,0) -> 0 | L29: 0 | M29: 0 | N29: 0 | O29: 00:00 | P29: ---
B30: سه‌شنبه | C30: 1405/02/22 | D30: 2 | E30: 06:06 | F30: 20:16 | G30: 0.59027778 | H30: 0.375 | I30: =MAX(H30-IF(R30="",0,R30),0) -> 0.375 | J30: =IF(G30>I30,G30-I30,0) -> 0.21527778 | K30: =IF(I30>G30,I30-G30,0) -> 0 | L30: 0 | M30: 0 | N30: 0 | O30: 00:00 | P30: ---
B31: چهارشنبه | C31: 1405/02/23 | D31: 2 | E31: 06:05 | F31: 20:03 | G31: 0.58194444 | H31: 0.33333333 | I31: =MAX(H31-IF(R31="",0,R31),0) -> 0.33333333 | J31: =IF(G31>I31,G31-I31,0) -> 0.24861111 | K31: =IF(I31>G31,I31-G31,0) -> 0 | L31: 0 | M31: 0 | N31: 0 | O31: 00:00 | P31: ---
B32: پنجشنبه | C32: 1405/02/24 | D32: 2 | E32: 06:00 | F32: 0.68055556 | G32: 0.43055556 | H32: 0 | I32: =MAX(H32-IF(R32="",0,R32),0) -> 0 | J32: 0 | K32: 0 | L32: 0 | M32: 0.43055556 | N32: 0 | O32: 00:00 | P32: ---
B33: جمعه | C33: 1405/02/25 | E33: ---- | F33: ---- | G33: 0 | H33: 0 | I33: 0 | J33: 0 | K33: 0 | L33: 0 | M33: 0 | N33: 0 | O33: 00:00 | P33: ---
B34: جمع | D34: =SUM(D3:D33) -> 50 | G34: =SUM(G3:G33) -> 13.68125 | H34: =SUM(H3:H33) -> 7.6666667 | I34: =SUM(I3:I33) -> 7.6666667 | J34: =SUM(J3:J33) -> 4.2791667 | K34: =SUM(K3:K33) -> 0 | L34: =SUM(L3:L33) -> 0 | M34: =SUM(M3:M33) -> 1.7354167 | N34: =SUM(N3:N33) -> 0 | Q34: =SUM(Q3:Q33) -> 0 | R34: =SUM(R3:R33) -> 0 | S34: =SUM(S3:S33) -> 0
H36: =IF(J34>=K34, J34-K34, 0) -> 4.2791667 | I36: اضافه کار واقعی
H37: =IF(K34<=J34, M34, IF(K34<=J34+M34, J34+M34-K34, 0)) -> 1.7354167 | I37: تعطیل کار واقعی
H38: =L34 -> 0 | I38: جمعه کاری
H39: =N34 -> 0 | I39: شبکاری
H40: =IF(K34>J34+M34, K34-J34-M34, 0) -> 0 | I40: کسرکار

Sheet حمید سوری
A1: شرکت توسعه کارآفرینی سوره کارکرد اردیبهشت 1405-حمید سوری
B2: روز | C2: تاریخ | D2: تعداد تردد | E2: اولین ورود | F2: آخرین خروج | G2: کارکرد | H2: کارکرد موظفی | I2: کارکرد موظف پس از کسر مرخصی | J2: اضافه کار | K2: کسرکار | L2: جمعه کاری | M2: تعطیل کاری | N2: شب کاری | O2: مرخصی | P2: نوع مرخصی | Q2: مرخصی استحقاقی | R2: مرخصی ساعتی | S2: مرخصی استعلاجی
